Workbook

Sheet Dashboard
A1: MahaKarya Studio — Dashboard operasional
A2: Dibuka tiap pagi. Ganti bulan di B4 (format yyyy-mm) atau biarkan: otomatis bulan ini.
A4: Bulan | B4: =TEXT(TODAY(),"yyyy-mm") -> 2026-10 | C4: ← ketik bulan lain (mis. 2025-11) untuk melihat bulan itu
A6: PENJUALAN BULAN INI | N6: PERINGATAN STOK
A7: Pesanan masuk | C7: Terbayar | E7: Konversi chat → bayar | G7: Omzet lampu | I7: Laba kotor (perkiraan) | K7: Rata hari bayar → tiba | N7: Filamen | O7: Sisa (g) | P7: Hari tersisa
A8: =COUNTIFS(Pesanan!$U$2:$U$1000,$B$4) -> 0 | C8: =SUMPRODUCT((Pesanan!$U$2:$U$1000=$B$4)*Pesanan!$W$2:$W$1000) -> 0 | E8: =IF(COUNTIFS(Pesanan!$U$2:$U$1000,$B$4)=0,"",SUMPRODUCT((Pesanan!$U$2:$U$1000=$B$4)*Pesanan!$W$2:$W$1000)/COUNTIFS(Pesanan!$U$2:$U$1000,$B$4)) | G8: =SUMIFS(Pesanan!$G$2:$G$1000,Pesanan!$V$2:$V$1000,$B$4,Pesanan!$W$2:$W$1000,1) -> 0 | I8: =SUMIFS(Pesanan!$AN$2:$AN$1000,Pesanan!$V$2:$V$1000,$B$4,Pesanan!$W$2:$W$1000,1) -> 0 | K8: =IF(COUNTIFS(Pesanan!$V$2:$V$1000,$B$4,Pesanan!$S$2:$S$1000,">=0")=0,"",SUMIFS(Pesanan!$S$2:$S$1000,Pesanan!$V$2:$V$1000,$B$4)/COUNTIFS(Pesanan!$V$2:$V$1000,$B$4,Pesanan!$S$2:$S$1000,">=0")) | N8: =IFERROR(INDEX('Stok filamen'!$B$5:$B$11,MATCH(1,'Stok filamen'!$N$5:$N$11,0)),"") | O8: =IFERROR(INDEX('Stok filamen'!$I$5:$I$11,MATCH(1,'Stok filamen'!$N$5:$N$11,0)),"") | P8: =IFERROR(INDEX('Stok filamen'!$L$5:$L$11,MATCH(1,'Stok filamen'!$N$5:$N$11,0)),"")
A9: chat yang jadi baris pesanan | C9: dari pesanan bulan ini | E9: target ≥ 40% | G9: pesanan dibayar bulan ini | I9: omzet − HPP asumsi Pengaturan | K9: target ≤ 8 hari | N9: =IFERROR(INDEX('Stok filamen'!$B$5:$B$11,MATCH(2,'Stok filamen'!$N$5:$N$11,0)),"") | O9: =IFERROR(INDEX('Stok filamen'!$I$5:$I$11,MATCH(2,'Stok filamen'!$N$5:$N$11,0)),"") | P9: =IFERROR(INDEX('Stok filamen'!$L$5:$L$11,MATCH(2,'Stok filamen'!$N$5:$N$11,0)),"")
N10: =IFERROR(INDEX('Stok filamen'!$B$5:$B$11,MATCH(3,'Stok filamen'!$N$5:$N$11,0)),"") | O10: =IFERROR(INDEX('Stok filamen'!$I$5:$I$11,MATCH(3,'Stok filamen'!$N$5:$N$11,0)),"") | P10: =IFERROR(INDEX('Stok filamen'!$L$5:$L$11,MATCH(3,'Stok filamen'!$N$5:$N$11,0)),"")
A11: HARUS DIKERJAKAN HARI INI (semua bulan) | N11: =IFERROR(INDEX('Stok filamen'!$B$5:$B$11,MATCH(4,'Stok filamen'!$N$5:$N$11,0)),"") | O11: =IFERROR(INDEX('Stok filamen'!$I$5:$I$11,MATCH(4,'Stok filamen'!$N$5:$N$11,0)),"") | P11: =IFERROR(INDEX('Stok filamen'!$L$5:$L$11,MATCH(4,'Stok filamen'!$N$5:$N$11,0)),"")
A12: Belum dibalas (Baru) | C12: Menunggu bayar > 1 hari | E12: Dalam antrean cetak | G12: Terlambat dari janji | I12: Dikirim, belum selesai | K12: Pesanan aktif | N12: =IFERROR(INDEX('Stok filamen'!$B$5:$B$11,MATCH(5,'Stok filamen'!$N$5:$N$11,0)),"") | O12: =IFERROR(INDEX('Stok filamen'!$I$5:$I$11,MATCH(5,'Stok filamen'!$N$5:$N$11,0)),"") | P12: =IFERROR(INDEX('Stok filamen'!$L$5:$L$11,MATCH(5,'Stok filamen'!$N$5:$N$11,0)),"")
A13: =COUNTIF(Pesanan!$C$2:$C$1000,"Baru") -> 0 | C13: =SUMPRODUCT((Pesanan!$C$2:$C$1000="Tunggu bayar")*(Pesanan!$B$2:$B$1000<TODAY()-1)*(Pesanan!$B$2:$B$1000<>"")) -> 1 | E13: =COUNTIF(Pesanan!$C$2:$C$1000,"Cetak") -> 1 | G13: =COUNTIF(Pesanan!$T$2:$T$1000,"YA") -> 1 | I13: =COUNTIF(Pesanan!$C$2:$C$1000,"Dikirim") -> 0 | K13: =COUNTIF(Pesanan!$A$2:$A$1000,"?*")-COUNTIF(Pesanan!$C$2:$C$1000,"Selesai")-COUNTIF(Pesanan!$C$2:$C$1000,"Batal") -> 2 | N13: =IFERROR(INDEX('Stok filamen'!$B$5:$B$11,MATCH(6,'Stok filamen'!$N$5:$N$11,0)),"") | O13: =IFERROR(INDEX('Stok filamen'!$I$5:$I$11,MATCH(6,'Stok filamen'!$N$5:$N$11,0)),"") | P13: =IFERROR(INDEX('Stok filamen'!$L$5:$L$11,MATCH(6,'Stok filamen'!$N$5:$N$11,0)),"")
A14: balas < 15 menit | C14: ingatkan sekali (/ingat) | E14: kelompokkan per warna | G14: Cetak lewat janji selesai → kabari pembeli | I14: H+3 tiba: tanya kabar (/selesai) | K14: semua selain Selesai/Batal | N14: =IFERROR(INDEX('Stok filamen'!$B$5:$B$11,MATCH(7,'Stok filamen'!$N$5:$N$11,0)),"") | O14: =IFERROR(INDEX('Stok filamen'!$I$5:$I$11,MATCH(7,'Stok filamen'!$N$5:$N$11,0)),"") | P14: =IFERROR(INDEX('Stok filamen'!$L$5:$L$11,MATCH(7,'Stok filamen'!$N$5:$N$11,0)),"")
A16: STOK & KAS | N16: Bahan | O16: Sisa | P16: Minimum
A17: Filamen perlu dipesan | C17: Bahan perlu dipesan | E17: Bagian jadi perlu dicetak | G17: Kas masuk bulan ini | I17: Kas keluar bulan ini | K17: Saldo kas (semua waktu) | N17: =IFERROR(INDEX('Stok bahan'!$A$5:$A$13,MATCH(1,'Stok bahan'!$N$5:$N$13,0)),"") | O17: =IFERROR(INDEX('Stok bahan'!$I$5:$I$13,MATCH(1,'Stok bahan'!$N$5:$N$13,0)),"") | P17: =IFERROR(INDEX('Stok bahan'!$J$5:$J$13,MATCH(1,'Stok bahan'!$N$5:$N$13,0)),"")
A18: =COUNTIF('Stok filamen'!$M$5:$M$11,"PESAN") -> 0 | C18: =COUNTIF('Stok bahan'!$K$5:$K$13,"PESAN") -> 0 | E18: =COUNTIF('Stok bagian jadi'!$G$5:$G$42,"CETAK") -> 0 | G18: =SUMIFS(Kas!$D$2:$D$2000,Kas!$B$2:$B$2000,"Masuk",Kas!$G$2:$G$2000,$B$4) -> 0 | I18: =SUMIFS(Kas!$D$2:$D$2000,Kas!$B$2:$B$2000,"Keluar",Kas!$G$2:$G$2000,$B$4) -> 0 | K18: =SUMIFS(Kas!$D$2:$D$2000,Kas!$B$2:$B$2000,"Masuk")-SUMIFS(Kas!$D$2:$D$2000,Kas!$B$2:$B$2000,"Keluar") -> -2546000 | N18: =IFERROR(INDEX('Stok bahan'!$A$5:$A$13,MATCH(2,'Stok bahan'!$N$5:$N$13,0)),"") | O18: =IFERROR(INDEX('Stok bahan'!$I$5:$I$13,MATCH(2,'Stok bahan'!$N$5:$N$13,0)),"") | P18: =IFERROR(INDEX('Stok bahan'!$J$5:$J$13,MATCH(2,'Stok bahan'!$N$5:$N$13,0)),"")
A19: lihat daftar di kanan | C19: dus, kit, LED, dll. | E19: stok preset di bawah minimum | K19: harus = saldo rekening bisnis | N19: =IFERROR(INDEX('Stok bahan'!$A$5:$A$13,MATCH(3,'Stok bahan'!$N$5:$N$13,0)),"") | O19: =IFERROR(INDEX('Stok bahan'!$I$5:$I$13,MATCH(3,'Stok bahan'!$N$5:$N$13,0)),"") | P19: =IFERROR(INDEX('Stok bahan'!$J$5:$J$13,MATCH(3,'Stok bahan'!$N$5:$N$13,0)),"")
N20: =IFERROR(INDEX('Stok bahan'!$A$5:$A$13,MATCH(4,'Stok bahan'!$N$5:$N$13,0)),"") | O20: =IFERROR(INDEX('Stok bahan'!$I$5:$I$13,MATCH(4,'Stok bahan'!$N$5:$N$13,0)),"") | P20: =IFERROR(INDEX('Stok bahan'!$J$5:$J$13,MATCH(4,'Stok bahan'!$N$5:$N$13,0)),"")
A21: 6 BULAN TERAKHIR (dari Laporan bulanan) | N21: =IFERROR(INDEX('Stok bahan'!$A$5:$A$13,MATCH(5,'Stok bahan'!$N$5:$N$13,0)),"") | O21: =IFERROR(INDEX('Stok bahan'!$I$5:$I$13,MATCH(5,'Stok bahan'!$N$5:$N$13,0)),"") | P21: =IFERROR(INDEX('Stok bahan'!$J$5:$J$13,MATCH(5,'Stok bahan'!$N$5:$N$13,0)),"")
A22: Bulan | B22: Pesanan | C22: Terbayar | D22: Konversi | E22: Omzet | F22: Laba kotor | G22: Kas bersih | H22: Hari bayar→tiba | N22: =IFERROR(INDEX('Stok bahan'!$A$5:$A$13,MATCH(6,'Stok bahan'!$N$5:$N$13,0)),"") | O22: =IFERROR(INDEX('Stok bahan'!$I$5:$I$13,MATCH(6,'Stok bahan'!$N$5:$N$13,0)),"") | P22: =IFERROR(INDEX('Stok bahan'!$J$5:$J$13,MATCH(6,'Stok bahan'!$N$5:$N$13,0)),"")
A23: =TEXT(EDATE(DATE(VALUE(LEFT($B$4,4)),VALUE(RIGHT($B$4,2)),1),-5),"yyyy-mm") -> 2026-05 | B23: =IFERROR(INDEX('Laporan bulanan'!$B$5:$B$22,MATCH(A23,'Laporan bulanan'!$A$5:$A$22,0)),"") -> 0 | C23: =IFERROR(INDEX('Laporan bulanan'!$C$5:$C$22,MATCH(A23,'Laporan bulanan'!$A$5:$A$22,0)),"") -> 0 | D23: =IFERROR(INDEX('Laporan bulanan'!$D$5:$D$22,MATCH(A23,'Laporan bulanan'!$A$5:$A$22,0)),"") | E23: =IFERROR(INDEX('Laporan bulanan'!$E$5:$E$22,MATCH(A23,'Laporan bulanan'!$A$5:$A$22,0)),"") -> 0 | F23: =IFERROR(INDEX('Laporan bulanan'!$H$5:$H$22,MATCH(A23,'Laporan bulanan'!$A$5:$A$22,0)),"") -> 0 | G23: =IFERROR(INDEX('Laporan bulanan'!$L$5:$L$22,MATCH(A23,'Laporan bulanan'!$A$5:$A$22,0)),"") -> 0 | H23: =IFERROR(INDEX('Laporan bulanan'!$M$5:$M$22,MATCH(A23,'Laporan bulanan'!$A$5:$A$22,0)),"") | N23: =IFERROR(INDEX('Stok bahan'!$A$5:$A$13,MATCH(7,'Stok bahan'!$N$5:$N$13,0)),"") | O23: =IFERROR(INDEX('Stok bahan'!$I$5:$I$13,MATCH(7,'Stok bahan'!$N$5:$N$13,0)),"") | P23: =IFERROR(INDEX('Stok bahan'!$J$5:$J$13,MATCH(7,'Stok bahan'!$N$5:$N$13,0)),"")
A24: =TEXT(EDATE(DATE(VALUE(LEFT($B$4,4)),VALUE(RIGHT($B$4,2)),1),-4),"yyyy-mm") -> 2026-06 | B24: =IFERROR(INDEX('Laporan bulanan'!$B$5:$B$22,MATCH(A24,'Laporan bulanan'!$A$5:$A$22,0)),"") -> 0 | C24: =IFERROR(INDEX('Laporan bulanan'!$C$5:$C$22,MATCH(A24,'Laporan bulanan'!$A$5:$A$22,0)),"") -> 0 | D24: =IFERROR(INDEX('Laporan bulanan'!$D$5:$D$22,MATCH(A24,'Laporan bulanan'!$A$5:$A$22,0)),"") | E24: =IFERROR(INDEX('Laporan bulanan'!$E$5:$E$22,MATCH(A24,'Laporan bulanan'!$A$5:$A$22,0)),"") -> 0 | F24: =IFERROR(INDEX('Laporan bulanan'!$H$5:$H$22,MATCH(A24,'Laporan bulanan'!$A$5:$A$22,0)),"") -> 0 | G24: =IFERROR(INDEX('Laporan bulanan'!$L$5:$L$22,MATCH(A24,'Laporan bulanan'!$A$5:$A$22,0)),"") -> 0 | H24: =IFERROR(INDEX('Laporan bulanan'!$M$5:$M$22,MATCH(A24,'Laporan bulanan'!$A$5:$A$22,0)),"")
A25: =TEXT(EDATE(DATE(VALUE(LEFT($B$4,4)),VALUE(RIGHT($B$4,2)),1),-3),"yyyy-mm") -> 2026-07 | B25: =IFERROR(INDEX('Laporan bulanan'!$B$5:$B$22,MATCH(A25,'Laporan bulanan'!$A$5:$A$22,0)),"") -> 0 | C25: =IFERROR(INDEX('Laporan bulanan'!$C$5:$C$22,MATCH(A25,'Laporan bulanan'!$A$5:$A$22,0)),"") -> 0 | D25: =IFERROR(INDEX('Laporan bulanan'!$D$5:$D$22,MATCH(A25,'Laporan bulanan'!$A$5:$A$22,0)),"") | E25: =IFERROR(INDEX('Laporan bulanan'!$E$5:$E$22,MATCH(A25,'Laporan bulanan'!$A$5:$A$22,0)),"") -> 0 | F25: =IFERROR(INDEX('Laporan bulanan'!$H$5:$H$22,MATCH(A25,'Laporan bulanan'!$A$5:$A$22,0)),"") -> 0 | G25: =IFERROR(INDEX('Laporan bulanan'!$L$5:$L$22,MATCH(A25,'Laporan bulanan'!$A$5:$A$22,0)),"") -> 0 | H25: =IFERROR(INDEX('Laporan bulanan'!$M$5:$M$22,MATCH(A25,'Laporan bulanan'!$A$5:$A$22,0)),"")
A26: =TEXT(EDATE(DATE(VALUE(LEFT($B$4,4)),VALUE(RIGHT($B$4,2)),1),-2),"yyyy-mm") -> 2026-08 | B26: =IFERROR(INDEX('Laporan bulanan'!$B$5:$B$22,MATCH(A26,'Laporan bulanan'!$A$5:$A$22,0)),"") -> 0 | C26: =IFERROR(INDEX('Laporan bulanan'!$C$5:$C$22,MATCH(A26,'Laporan bulanan'!$A$5:$A$22,0)),"") -> 0 | D26: =IFERROR(INDEX('Laporan bulanan'!$D$5:$D$22,MATCH(A26,'Laporan bulanan'!$A$5:$A$22,0)),"") | E26: =IFERROR(INDEX('Laporan bulanan'!$E$5:$E$22,MATCH(A26,'Laporan bulanan'!$A$5:$A$22,0)),"") -> 0 | F26: =IFERROR(INDEX('Laporan bulanan'!$H$5:$H$22,MATCH(A26,'Laporan bulanan'!$A$5:$A$22,0)),"") -> 0 | G26: =IFERROR(INDEX('Laporan bulanan'!$L$5:$L$22,MATCH(A26,'Laporan bulanan'!$A$5:$A$22,0)),"") -> 0 | H26: =IFERROR(INDEX('Laporan bulanan'!$M$5:$M$22,MATCH(A26,'Laporan bulanan'!$A$5:$A$22,0)),"")
A27: =TEXT(EDATE(DATE(VALUE(LEFT($B$4,4)),VALUE(RIGHT($B$4,2)),1),-1),"yyyy-mm") -> 2026-09 | B27: =IFERROR(INDEX('Laporan bulanan'!$B$5:$B$22,MATCH(A27,'Laporan bulanan'!$A$5:$A$22,0)),"") -> 0 | C27: =IFERROR(INDEX('Laporan bulanan'!$C$5:$C$22,MATCH(A27,'Laporan bulanan'!$A$5:$A$22,0)),"") -> 0 | D27: =IFERROR(INDEX('Laporan bulanan'!$D$5:$D$22,MATCH(A27,'Laporan bulanan'!$A$5:$A$22,0)),"") | E27: =IFERROR(INDEX('Laporan bulanan'!$E$5:$E$22,MATCH(A27,'Laporan bulanan'!$A$5:$A$22,0)),"") -> 0 | F27: =IFERROR(INDEX('Laporan bulanan'!$H$5:$H$22,MATCH(A27,'Laporan bulanan'!$A$5:$A$22,0)),"") -> 0 | G27: =IFERROR(INDEX('Laporan bulanan'!$L$5:$L$22,MATCH(A27,'Laporan bulanan'!$A$5:$A$22,0)),"") -> 0 | H27: =IFERROR(INDEX('Laporan bulanan'!$M$5:$M$22,MATCH(A27,'Laporan bulanan'!$A$5:$A$22,0)),"")
A28: =TEXT(EDATE(DATE(VALUE(LEFT($B$4,4)),VALUE(RIGHT($B$4,2)),1),0),"yyyy-mm") -> 2026-10 | B28: =IFERROR(INDEX('Laporan bulanan'!$B$5:$B$22,MATCH(A28,'Laporan bulanan'!$A$5:$A$22,0)),"") -> 0 | C28: =IFERROR(INDEX('Laporan bulanan'!$C$5:$C$22,MATCH(A28,'Laporan bulanan'!$A$5:$A$22,0)),"") -> 0 | D28: =IFERROR(INDEX('Laporan bulanan'!$D$5:$D$22,MATCH(A28,'Laporan bulanan'!$A$5:$A$22,0)),"") | E28: =IFERROR(INDEX('Laporan bulanan'!$E$5:$E$22,MATCH(A28,'Laporan bulanan'!$A$5:$A$22,0)),"") -> 0 | F28: =IFERROR(INDEX('Laporan bulanan'!$H$5:$H$22,MATCH(A28,'Laporan bulanan'!$A$5:$A$22,0)),"") -> 0 | G28: =IFERROR(INDEX('Laporan bulanan'!$L$5:$L$22,MATCH(A28,'Laporan bulanan'!$A$5:$A$22,0)),"") -> 0 | H28: =IFERROR(INDEX('Laporan bulanan'!$M$5:$M$22,MATCH(A28,'Laporan bulanan'!$A$5:$A$22,0)),"")
A30: Grafik: blok A22:H28 → Sisipkan → Diagram (Google Sheets membuat grafik kolom otomatis). Dashboard ini hanya rumus; data mentahnya di tab Pesanan, Kas, Mutasi stok.

Sheet Pesanan
A1: ID | B1: Tanggal | C1: Status | D1: Nama | E1: No WA | F1: Kode rakitan | G1: Harga lampu | H1: Zona | I1: Ongkir | J1: Alamat | K1: Tgl bayar | L1: Janji selesai | M1: Kurir | N1: Resi | O1: Perkiraan tiba | P1: Tgl selesai | Q1: Catatan | R1: Total | S1: Hari bayar→tiba | T1: Terlambat? | U1: Bulan pesan | V1: Bulan bayar | W1: Terbayar? | X1: Kode bersih | Y1: Jml segmen | Z1: Kap | AA1: Badan 1 | AB1: Badan 2 | AC1: Badan 3 | AD1: Alas | AE1: Kit? | AF1: LED? | AG1: g kap | AH1: g badan 1 | AI1: g badan 2 | AJ1: g badan 3 | AK1: g alas | AL1: Total gram | AM1: HPP | AN1: Laba kotor | AO1: Margin
A2: P251001-01 | B2: 45931 | C2: Selesai | D2: Contoh A (hapus) | E2: 62812xxxxxxx | F2: MK-KERGAD-KUBBAT-HEKKRE-BOLSAL-KOTBAT | G2: 439000 | H2: Jabodetabek | I2: 20000 | J2: Jl. Contoh 1, Jakarta Selatan | K2: 45932 | L2: 45937 | M2: JNE | N2: JNE0001 | O2: 45939 | P2: 45942 | Q2: Baris contoh, hapus | R2: =IF(A2="","",N(G2)+N(I2)) -> 459000 | S2: =IF(OR(K2="",O2=""),"",O2-K2) -> 7 | T2: =IF(AND(C2="Cetak",L2<>"",L2<TODAY()),"YA","") | U2: =IF(B2="","",TEXT(B2,"yyyy-mm")) -> 2025-10 | V2: =IF(K2="","",TEXT(K2,"yyyy-mm")) -> 2025-10 | W2: =IF(OR(C2="Cetak",C2="Dikirim",C2="Selesai"),1,0) -> 1 | X2: =IF(F2="","",SUBSTITUTE(SUBSTITUTE(MID(UPPER(TRIM(F2)),4,99),"-LED",""),"-TK","")) -> KERGAD-KUBBAT-HEKKRE-BOLSAL-KOTBAT | Y2: =IF(X2="","",(LEN(X2)+1)/7) -> 5 | Z2: =IF(X2="","",LEFT(X2,6)) -> KERGAD | AA2: =IF(X2="","",IF(Y2>=3,MID(X2,8,6),"")) -> KUBBAT | AB2: =IF(X2="","",IF(Y2>=4,MID(X2,15,6),"")) -> HEKKRE | AC2: =IF(X2="","",IF(Y2>=5,MID(X2,22,6),"")) -> BOLSAL | AD2: =IF(X2="","",RIGHT(X2,6)) -> KOTBAT | AE2: =IF(F2="","",IF(ISNUMBER(SEARCH("-TK",UPPER(F2))),0,1)) -> 1 | AF2: =IF(F2="","",IF(ISNUMBER(SEARCH("-LED",UPPER(F2))),1,0)) -> 0 | AG2: =IF(Z2="",0,IFERROR(INDEX(Resep!$C$5:$C$7,MATCH(LEFT(Z2,3),Resep!$B$5:$B$7,0)),0)) -> 170 | AH2: =IF(AA2="",0,IFERROR(INDEX(Resep!$C$9:$C$13,MATCH(LEFT(AA2,3),Resep!$B$9:$B$13,0)),0)) -> 170 | AI2: =IF(AB2="",0,IFERROR(INDEX(Resep!$C$9:$C$13,MATCH(LEFT(AB2,3),Resep!$B$9:$B$13,0)),0)) -> 190 | AJ2: =IF(AC2="",0,IFERROR(INDEX(Resep!$C$9:$C$13,MATCH(LEFT(AC2,3),Resep!$B$9:$B$13,0)),0)) -> 180 | AK2: =IF(AD2="",0,IFERROR(INDEX(Resep!$C$15:$C$18,MATCH(LEFT(AD2,3),Resep!$B$15:$B$18,0)),0)) -> 220 | AL2: =IF(X2="","",AG2+AH2+AI2+AJ2+AK2) -> 930 | AM2: =IF(X2="","",AL2*(Pengaturan!$B$6+Pengaturan!$B$7)+Pengaturan!$B$8+AE2*Pengaturan!$B$9+AF2*Pengaturan!$B$10) -> 280850 | AN2: =IF(X2="","",N(G2)-AM2) -> 158150 | AO2: =IF(OR(X2="",N(G2)=0),"",AN2/G2) -> 0.36025057
A3: P251003-02 | B3: 45933 | C3: Cetak | D3: Contoh B (hapus) | E3: 62813xxxxxxx | F3: MK-PLIGAD-BOLZAI-BULHIT-LED | G3: 385000 | H3: Pulau Jawa | I3: 45000 | J3: Jl. Contoh 2, Bandung | K3: 45934 | L3: 45939 | Q3: Baris contoh, hapus | R3: =IF(A3="","",N(G3)+N(I3)) -> 430000 | S3: =IF(OR(K3="",O3=""),"",O3-K3) | T3: =IF(AND(C3="Cetak",L3<>"",L3<TODAY()),"YA","") -> YA | U3: =IF(B3="","",TEXT(B3,"yyyy-mm")) -> 2025-10 | V3: =IF(K3="","",TEXT(K3,"yyyy-mm")) -> 2025-10 | W3: =IF(OR(C3="Cetak",C3="Dikirim",C3="Selesai"),1,0) -> 1 | X3: =IF(F3="","",SUBSTITUTE(SUBSTITUTE(MID(UPPER(TRIM(F3)),4,99),"-LED",""),"-TK","")) -> PLIGAD-BOLZAI-BULHIT | Y3: =IF(X3="","",(LEN(X3)+1)/7) -> 3 | Z3: =IF(X3="","",LEFT(X3,6)) -> PLIGAD | AA3: =IF(X3="","",IF(Y3>=3,MID(X3,8,6),"")) -> BOLZAI | AB3: =IF(X3="","",IF(Y3>=4,MID(X3,15,6),"")) | AC3: =IF(X3="","",IF(Y3>=5,MID(X3,22,6),"")) | AD3: =IF(X3="","",RIGHT(X3,6)) -> BULHIT | AE3: =IF(F3="","",IF(ISNUMBER(SEARCH("-TK",UPPER(F3))),0,1)) -> 1 | AF3: =IF(F3="","",IF(ISNUMBER(SEARCH("-LED",UPPER(F3))),1,0)) -> 1 | AG3: =IF(Z3="",0,IFERROR(INDEX(Resep!$C$5:$C$7,MATCH(LEFT(Z3,3),Resep!$B$5:$B$7,0)),0)) -> 200 | AH3: =IF(AA3="",0,IFERROR(INDEX(Resep!$C$9:$C$13,MATCH(LEFT(AA3,3),Resep!$B$9:$B$13,0)),0)) -> 180 | AI3: =IF(AB3="",0,IFERROR(INDEX(Resep!$C$9:$C$13,MATCH(LEFT(AB3,3),Resep!$B$9:$B$13,0)),0)) -> 0 | AJ3: =IF(AC3="",0,IFERROR(INDEX(Resep!$C$9:$C$13,MATCH(LEFT(AC3,3),Resep!$B$9:$B$13,0)),0)) -> 0 | AK3: =IF(AD3="",0,IFERROR(INDEX(Resep!$C$15:$C$18,MATCH(LEFT(AD3,3),Resep!$B$15:$B$18,0)),0)) -> 220 | AL3: =IF(X3="","",AG3+AH3+AI3+AJ3+AK3) -> 600 | AM3: =IF(X3="","",AL3*(Pengaturan!$B$6+Pengaturan!$B$7)+Pengaturan!$B$8+AE3*Pengaturan!$B$9+AF3*Pengaturan!$B$10) -> 215000 | AN3: =IF(X3="","",N(G3)-AM3) -> 170000 | AO3: =IF(OR(X3="",N(G3)=0),"",AN3/G3) -> 0.44155844
A4: P251004-03 | B4: 45934 | C4: Tunggu bayar | D4: Contoh C (hapus) | E4: 62815xxxxxxx | F4: MK-KOTPUT-CINHIT-BOLKRE-BUNSAL-TK | G4: 360000 | H4: Jabodetabek | I4: 20000 | J4: Jl. Contoh 3, Depok | Q4: Baris contoh, hapus | R4: =IF(A4="","",N(G4)+N(I4)) -> 380000 | S4: =IF(OR(K4="",O4=""),"",O4-K4) | T4: =IF(AND(C4="Cetak",L4<>"",L4<TODAY()),"YA","") | U4: =IF(B4="","",TEXT(B4,"yyyy-mm")) -> 2025-10 | V4: =IF(K4="","",TEXT(K4,"yyyy-mm")) | W4: =IF(OR(C4="Cetak",C4="Dikirim",C4="Selesai"),1,0) -> 0 | X4: =IF(F4="","",SUBSTITUTE(SUBSTITUTE(MID(UPPER(TRIM(F4)),4,99),"-LED",""),"-TK","")) -> KOTPUT-CINHIT-BOLKRE-BUNSAL | Y4: =IF(X4="","",(LEN(X4)+1)/7) -> 4 | Z4: =IF(X4="","",LEFT(X4,6)) -> KOTPUT | AA4: =IF(X4="","",IF(Y4>=3,MID(X4,8,6),"")) -> CINHIT | AB4: =IF(X4="","",IF(Y4>=4,MID(X4,15,6),"")) -> BOLKRE | AC4: =IF(X4="","",IF(Y4>=5,MID(X4,22,6),"")) | AD4: =IF(X4="","",RIGHT(X4,6)) -> BUNSAL | AE4: =IF(F4="","",IF(ISNUMBER(SEARCH("-TK",UPPER(F4))),0,1)) -> 0 | AF4: =IF(F4="","",IF(ISNUMBER(SEARCH("-LED",UPPER(F4))),1,0)) -> 0 | AG4: =IF(Z4="",0,IFERROR(INDEX(Resep!$C$5:$C$7,MATCH(LEFT(Z4,3),Resep!$B$5:$B$7,0)),0)) -> 190 | AH4: =IF(AA4="",0,IFERROR(INDEX(Resep!$C$9:$C$13,MATCH(LEFT(AA4,3),Resep!$B$9:$B$13,0)),0)) -> 120 | AI4: =IF(AB4="",0,IFERROR(INDEX(Resep!$C$9:$C$13,MATCH(LEFT(AB4,3),Resep!$B$9:$B$13,0)),0)) -> 180 | AJ4: =IF(AC4="",0,IFERROR(INDEX(Resep!$C$9:$C$13,MATCH(LEFT(AC4,3),Resep!$B$9:$B$13,0)),0)) -> 0 | AK4: =IF(AD4="",0,IFERROR(INDEX(Resep!$C$15:$C$18,MATCH(LEFT(AD4,3),Resep!$B$15:$B$18,0)),0)) -> 240 | AL4: =IF(X4="","",AG4+AH4+AI4+AJ4+AK4) -> 730 | AM4: =IF(X4="","",AL4*(Pengaturan!$B$6+Pengaturan!$B$7)+Pengaturan!$B$8+AE4*Pengaturan!$B$9+AF4*Pengaturan!$B$10) -> 196850 | AN4: =IF(X4="","",N(G4)-AM4) -> 163150 | AO4: =IF(OR(X4="",N(G4)=0),"",AN4/G4) -> 0.45319444
R5: =IF(A5="","",N(G5)+N(I5)) | S5: =IF(OR(K5="",O5=""),"",O5-K5) | T5: =IF(AND(C5="Cetak",L5<>"",L5<TODAY()),"YA","") | U5: =IF(B5="","",TEXT(B5,"yyyy-mm")) | V5: =IF(K5="","",TEXT(K5,"yyyy-mm")) | W5: =IF(OR(C5="Cetak",C5="Dikirim",C5="Selesai"),1,0) -> 0 | X5: =IF(F5="","",SUBSTITUTE(SUBSTITUTE(MID(UPPER(TRIM(F5)),4,99),"-LED",""),"-TK","")) | Y5: =IF(X5="","",(LEN(X5)+1)/7) | Z5: =IF(X5="","",LEFT(X5,6)) | AA5: =IF(X5="","",IF(Y5>=3,MID(X5,8,6),"")) | AB5: =IF(X5="","",IF(Y5>=4,MID(X5,15,6),"")) | AC5: =IF(X5="","",IF(Y5>=5,MID(X5,22,6),"")) | AD5: =IF(X5="","",RIGHT(X5,6)) | AE5: =IF(F5="","",IF(ISNUMBER(SEARCH("-TK",UPPER(F5))),0,1)) | AF5: =IF(F5="","",IF(ISNUMBER(SEARCH("-LED",UPPER(F5))),1,0)) | AG5: =IF(Z5="",0,IFERROR(INDEX(Resep!$C$5:$C$7,MATCH(LEFT(Z5,3),Resep!$B$5:$B$7,0)),0)) -> 0 | AH5: =IF(AA5="",0,IFERROR(INDEX(Resep!$C$9:$C$13,MATCH(LEFT(AA5,3),Resep!$B$9:$B$13,0)),0)) -> 0 | AI5: =IF(AB5="",0,IFERROR(INDEX(Resep!$C$9:$C$13,MATCH(LEFT(AB5,3),Resep!$B$9:$B$13,0)),0)) -> 0 | AJ5: =IF(AC5="",0,IFERROR(INDEX(Resep!$C$9:$C$13,MATCH(LEFT(AC5,3),Resep!$B$9:$B$13,0)),0)) -> 0 | AK5: =IF(AD5="",0,IFERROR(INDEX(Resep!$C$15:$C$18,MATCH(LEFT(AD5,3),Resep!$B$15:$B$18,0)),0)) -> 0 | AL5: =IF(X5="","",AG5+AH5+AI5+AJ5+AK5) | AM5: =IF(X5="","",AL5*(Pengaturan!$B$6+Pengaturan!$B$7)+Pengaturan!$B$8+AE5*Pengaturan!$B$9+AF5*Pengaturan!$B$10) | AN5: =IF(X5="","",N(G5)-AM5) | AO5: =IF(OR(X5="",N(G5)=0),"",AN5/G5)
R6: =IF(A6="","",N(G6)+N(I6)) | S6: =IF(OR(K6="",O6=""),"",O6-K6) | T6: =IF(AND(C6="Cetak",L6<>"",L6<TODAY()),"YA","") | U6: =IF(B6="","",TEXT(B6,"yyyy-mm")) | V6: =IF(K6="","",TEXT(K6,"yyyy-mm")) | W6: =IF(OR(C6="Cetak",C6="Dikirim",C6="Selesai"),1,0) -> 0 | X6: =IF(F6="","",SUBSTITUTE(SUBSTITUTE(MID(UPPER(TRIM(F6)),4,99),"-LED",""),"-TK","")) | Y6: =IF(X6="","",(LEN(X6)+1)/7) | Z6: =IF(X6="","",LEFT(X6,6)) | AA6: =IF(X6="","",IF(Y6>=3,MID(X6,8,6),"")) | AB6: =IF(X6="","",IF(Y6>=4,MID(X6,15,6),"")) | AC6: =IF(X6="","",IF(Y6>=5,MID(X6,22,6),"")) | AD6: =IF(X6="","",RIGHT(X6,6)) | AE6: =IF(F6="","",IF(ISNUMBER(SEARCH("-TK",UPPER(F6))),0,1)) | AF6: =IF(F6="","",IF(ISNUMBER(SEARCH("-LED",UPPER(F6))),1,0)) | AG6: =IF(Z6="",0,IFERROR(INDEX(Resep!$C$5:$C$7,MATCH(LEFT(Z6,3),Resep!$B$5:$B$7,0)),0)) -> 0 | AH6: =IF(AA6="",0,IFERROR(INDEX(Resep!$C$9:$C$13,MATCH(LEFT(AA6,3),Resep!$B$9:$B$13,0)),0)) -> 0 | AI6: =IF(AB6="",0,IFERROR(INDEX(Resep!$C$9:$C$13,MATCH(LEFT(AB6,3),Resep!$B$9:$B$13,0)),0)) -> 0 | AJ6: =IF(AC6="",0,IFERROR(INDEX(Resep!$C$9:$C$13,MATCH(LEFT(AC6,3),Resep!$B$9:$B$13,0)),0)) -> 0 | AK6: =IF(AD6="",0,IFERROR(INDEX(Resep!$C$15:$C$18,MATCH(LEFT(AD6,3),Resep!$B$15:$B$18,0)),0)) -> 0 | AL6: =IF(X6="","",AG6+AH6+AI6+AJ6+AK6) | AM6: =IF(X6="","",AL6*(Pengaturan!$B$6+Pengaturan!$B$7)+Pengaturan!$B$8+AE6*Pengaturan!$B$9+AF6*Pengaturan!$B$10) | AN6: =IF(X6="","",N(G6)-AM6) | AO6: =IF(OR(X6="",N(G6)=0),"",AN6/G6)
R7: =IF(A7="","",N(G7)+N(I7)) | S7: =IF(OR(K7="",O7=""),"",O7-K7) | T7: =IF(AND(C7="Cetak",L7<>"",L7<TODAY()),"YA","") | U7: =IF(B7="","",TEXT(B7,"yyyy-mm")) | V7: =IF(K7="","",TEXT(K7,"yyyy-mm")) | W7: =IF(OR(C7="Cetak",C7="Dikirim",C7="Selesai"),1,0) -> 0 | X7: =IF(F7="","",SUBSTITUTE(SUBSTITUTE(MID(UPPER(TRIM(F7)),4,99),"-LED",""),"-TK","")) | Y7: =IF(X7="","",(LEN(X7)+1)/7) | Z7: =IF(X7="","",LEFT(X7,6)) | AA7: =IF(X7="","",IF(Y7>=3,MID(X7,8,6),"")) | AB7: =IF(X7="","",IF(Y7>=4,MID(X7,15,6),"")) | AC7: =IF(X7="","",IF(Y7>=5,MID(X7,22,6),"")) | AD7: =IF(X7="","",RIGHT(X7,6)) | AE7: =IF(F7="","",IF(ISNUMBER(SEARCH("-TK",UPPER(F7))),0,1)) | AF7: =IF(F7="","",IF(ISNUMBER(SEARCH("-LED",UPPER(F7))),1,0)) | AG7: =IF(Z7="",0,IFERROR(INDEX(Resep!$C$5:$C$7,MATCH(LEFT(Z7,3),Resep!$B$5:$B$7,0)),0)) -> 0 | AH7: =IF(AA7="",0,IFERROR(INDEX(Resep!$C$9:$C$13,MATCH(LEFT(AA7,3),Resep!$B$9:$B$13,0)),0)) -> 0 | AI7: =IF(AB7="",0,IFERROR(INDEX(Resep!$C$9:$C$13,MATCH(LEFT(AB7,3),Resep!$B$9:$B$13,0)),0)) -> 0 | AJ7: =IF(AC7="",0,IFERROR(INDEX(Resep!$C$9:$C$13,MATCH(LEFT(AC7,3),Resep!$B$9:$B$13,0)),0)) -> 0 | AK7: =IF(AD7="",0,IFERROR(INDEX(Resep!$C$15:$C$18,MATCH(LEFT(AD7,3),Resep!$B$15:$B$18,0)),0)) -> 0 | AL7: =IF(X7="","",AG7+AH7+AI7+AJ7+AK7) | AM7: =IF(X7="","",AL7*(Pengaturan!$B$6+Pengaturan!$B$7)+Pengaturan!$B$8+AE7*Pengaturan!$B$9+AF7*Pengaturan!$B$10) | AN7: =IF(X7="","",N(G7)-AM7) | AO7: =IF(OR(X7="",N(G7)=0),"",AN7/G7)
R8: =IF(A8="","",N(G8)+N(I8)) | S8: =IF(OR(K8="",O8=""),"",O8-K8) | T8: =IF(AND(C8="Cetak",L8<>"",L8<TODAY()),"YA","") | U8: =IF(B8="","",TEXT(B8,"yyyy-mm")) | V8: =IF(K8="","",TEXT(K8,"yyyy-mm")) | W8: =IF(OR(C8="Cetak",C8="Dikirim",C8="Selesai"),1,0) -> 0 | X8: =IF(F8="","",SUBSTITUTE(SUBSTITUTE(MID(UPPER(TRIM(F8)),4,99),"-LED",""),"-TK","")) | Y8: =IF(X8="","",(LEN(X8)+1)/7) | Z8: =IF(X8="","",LEFT(X8,6)) | AA8: =IF(X8="","",IF(Y8>=3,MID(X8,8,6),"")) | AB8: =IF(X8="","",IF(Y8>=4,MID(X8,15,6),"")) | AC8: =IF(X8="","",IF(Y8>=5,MID(X8,22,6),"")) | AD8: =IF(X8="","",RIGHT(X8,6)) | AE8: =IF(F8="","",IF(ISNUMBER(SEARCH("-TK",UPPER(F8))),0,1)) | AF8: =IF(F8="","",IF(ISNUMBER(SEARCH("-LED",UPPER(F8))),1,0)) | AG8: =IF(Z8="",0,IFERROR(INDEX(Resep!$C$5:$C$7,MATCH(LEFT(Z8,3),Resep!$B$5:$B$7,0)),0)) -> 0 | AH8: =IF(AA8="",0,IFERROR(INDEX(Resep!$C$9:$C$13,MATCH(LEFT(AA8,3),Resep!$B$9:$B$13,0)),0)) -> 0 | AI8: =IF(AB8="",0,IFERROR(INDEX(Resep!$C$9:$C$13,MATCH(LEFT(AB8,3),Resep!$B$9:$B$13,0)),0)) -> 0 | AJ8: =IF(AC8="",0,IFERROR(INDEX(Resep!$C$9:$C$13,MATCH(LEFT(AC8,3),Resep!$B$9:$B$13,0)),0)) -> 0 | AK8: =IF(AD8="",0,IFERROR(INDEX(Resep!$C$15:$C$18,MATCH(LEFT(AD8,3),Resep!$B$15:$B$18,0)),0)) -> 0 | AL8: =IF(X8="","",AG8+AH8+AI8+AJ8+AK8) | AM8: =IF(X8="","",AL8*(Pengaturan!$B$6+Pengaturan!$B$7)+Pengaturan!$B$8+AE8*Pengaturan!$B$9+AF8*Pengaturan!$B$10) | AN8: =IF(X8="","",N(G8)-AM8) | AO8: =IF(OR(X8="",N(G8)=0),"",AN8/G8)
R9: =IF(A9="","",N(G9)+N(I9)) | S9: =IF(OR(K9="",O9=""),"",O9-K9) | T9: =IF(AND(C9="Cetak",L9<>"",L9<TODAY()),"YA","") | U9: =IF(B9="","",TEXT(B9,"yyyy-mm")) | V9: =IF(K9="","",TEXT(K9,"yyyy-mm")) | W9: =IF(OR(C9="Cetak",C9="Dikirim",C9="Selesai"),1,0) -> 0 | X9: =IF(F9="","",SUBSTITUTE(SUBSTITUTE(MID(UPPER(TRIM(F9)),4,99),"-LED",""),"-TK","")) | Y9: =IF(X9="","",(LEN(X9)+1)/7) | Z9: =IF(X9="","",LEFT(X9,6)) | AA9: =IF(X9="","",IF(Y9>=3,MID(X9,8,6),"")) | AB9: =IF(X9="","",IF(Y9>=4,MID(X9,15,6),"")) | AC9: =IF(X9="","",IF(Y9>=5,MID(X9,22,6),"")) | AD9: =IF(X9="","",RIGHT(X9,6)) | AE9: =IF(F9="","",IF(ISNUMBER(SEARCH("-TK",UPPER(F9))),0,1)) | AF9: =IF(F9="","",IF(ISNUMBER(SEARCH("-LED",UPPER(F9))),1,0)) | AG9: =IF(Z9="",0,IFERROR(INDEX(Resep!$C$5:$C$7,MATCH(LEFT(Z9,3),Resep!$B$5:$B$7,0)),0)) -> 0 | AH9: =IF(AA9="",0,IFERROR(INDEX(Resep!$C$9:$C$13,MATCH(LEFT(AA9,3),Resep!$B$9:$B$13,0)),0)) -> 0 | AI9: =IF(AB9="",0,IFERROR(INDEX(Resep!$C$9:$C$13,MATCH(LEFT(AB9,3),Resep!$B$9:$B$13,0)),0)) -> 0 | AJ9: =IF(AC9="",0,IFERROR(INDEX(Resep!$C$9:$C$13,MATCH(LEFT(AC9,3),Resep!$B$9:$B$13,0)),0)) -> 0 | AK9: =IF(AD9="",0,IFERROR(INDEX(Resep!$C$15:$C$18,MATCH(LEFT(AD9,3),Resep!$B$15:$B$18,0)),0)) -> 0 | AL9: =IF(X9="","",AG9+AH9+AI9+AJ9+AK9) | AM9: =IF(X9="","",AL9*(Pengaturan!$B$6+Pengaturan!$B$7)+Pengaturan!$B$8+AE9*Pengaturan!$B$9+AF9*Pengaturan!$B$10) | AN9: =IF(X9="","",N(G9)-AM9) | AO9: =IF(OR(X9="",N(G9)=0),"",AN9/G9)
R10: =IF(A10="","",N(G10)+N(I10)) | S10: =IF(OR(K10="",O10=""),"",O10-K10) | T10: =IF(AND(C10="Cetak",L10<>"",L10<TODAY()),"YA","") | U10: =IF(B10="","",TEXT(B10,"yyyy-mm")) | V10: =IF(K10="","",TEXT(K10,"yyyy-mm")) | W10: =IF(OR(C10="Cetak",C10="Dikirim",C10="Selesai"),1,0) -> 0 | X10: =IF(F10="","",SUBSTITUTE(SUBSTITUTE(MID(UPPER(TRIM(F10)),4,99),"-LED",""),"-TK","")) | Y10: =IF(X10="","",(LEN(X10)+1)/7) | Z10: =IF(X10="","",LEFT(X10,6)) | AA10: =IF(X10="","",IF(Y10>=3,MID(X10,8,6),"")) | AB10: =IF(X10="","",IF(Y10>=4,MID(X10,15,6),"")) | AC10: =IF(X10="","",IF(Y10>=5,MID(X10,22,6),"")) | AD10: =IF(X10="","",RIGHT(X10,6)) | AE10: =IF(F10="","",IF(ISNUMBER(SEARCH("-TK",UPPER(F10))),0,1)) | AF10: =IF(F10="","",IF(ISNUMBER(SEARCH("-LED",UPPER(F10))),1,0)) | AG10: =IF(Z10="",0,IFERROR(INDEX(Resep!$C$5:$C$7,MATCH(LEFT(Z10,3),Resep!$B$5:$B$7,0)),0)) -> 0 | AH10: =IF(AA10="",0,IFERROR(INDEX(Resep!$C$9:$C$13,MATCH(LEFT(AA10,3),Resep!$B$9:$B$13,0)),0)) -> 0 | AI10: =IF(AB10="",0,IFERROR(INDEX(Resep!$C$9:$C$13,MATCH(LEFT(AB10,3),Resep!$B$9:$B$13,0)),0)) -> 0 | AJ10: =IF(AC10="",0,IFERROR(INDEX(Resep!$C$9:$C$13,MATCH(LEFT(AC10,3),Resep!$B$9:$B$13,0)),0)) -> 0 | AK10: =IF(AD10="",0,IFERROR(INDEX(Resep!$C$15:$C$18,MATCH(LEFT(AD10,3),Resep!$B$15:$B$18,0)),0)) -> 0 | AL10: =IF(X10="","",AG10+AH10+AI10+AJ10+AK10) | AM10: =IF(X10="","",AL10*(Pengaturan!$B$6+Pengaturan!$B$7)+Pengaturan!$B$8+AE10*Pengaturan!$B$9+AF10*Pengaturan!$B$10) | AN10: =IF(X10="","",N(G10)-AM10) | AO10: =IF(OR(X10="",N(G10)=0),"",AN10/G10)
R11: =IF(A11="","",N(G11)+N(I11)) | S11: =IF(OR(K11="",O11=""),"",O11-K11) | T11: =IF(AND(C11="Cetak",L11<>"",L11<TODAY()),"YA","") | U11: =IF(B11="","",TEXT(B11,"yyyy-mm")) | V11: =IF(K11="","",TEXT(K11,"yyyy-mm")) | W11: =IF(OR(C11="Cetak",C11="Dikirim",C11="Selesai"),1,0) -> 0 | X11: =IF(F11="","",SUBSTITUTE(SUBSTITUTE(MID(UPPER(TRIM(F11)),4,99),"-LED",""),"-TK","")) | Y11: =IF(X11="","",(LEN(X11)+1)/7) | Z11: =IF(X11="","",LEFT(X11,6)) | AA11: =IF(X11="","",IF(Y11>=3,MID(X11,8,6),"")) | AB11: =IF(X11="","",IF(Y11>=4,MID(X11,15,6),"")) | AC11: =IF(X11="","",IF(Y11>=5,MID(X11,22,6),"")) | AD11: =IF(X11="","",RIGHT(X11,6)) | AE11: =IF(F11="","",IF(ISNUMBER(SEARCH("-TK",UPPER(F11))),0,1)) | AF11: =IF(F11="","",IF(ISNUMBER(SEARCH("-LED",UPPER(F11))),1,0)) | AG11: =IF(Z11="",0,IFERROR(INDEX(Resep!$C$5:$C$7,MATCH(LEFT(Z11,3),Resep!$B$5:$B$7,0)),0)) -> 0 | AH11: =IF(AA11="",0,IFERROR(INDEX(Resep!$C$9:$C$13,MATCH(LEFT(AA11,3),Resep!$B$9:$B$13,0)),0)) -> 0 | AI11: =IF(AB11="",0,IFERROR(INDEX(Resep!$C$9:$C$13,MATCH(LEFT(AB11,3),Resep!$B$9:$B$13,0)),0)) -> 0 | AJ11: =IF(AC11="",0,IFERROR(INDEX(Resep!$C$9:$C$13,MATCH(LEFT(AC11,3),Resep!$B$9:$B$13,0)),0)) -> 0 | AK11: =IF(AD11="",0,IFERROR(INDEX(Resep!$C$15:$C$18,MATCH(LEFT(AD11,3),Resep!$B$15:$B$18,0)),0)) -> 0 | AL11: =IF(X11="","",AG11+AH11+AI11+AJ11+AK11) | AM11: =IF(X11="","",AL11*(Pengaturan!$B$6+Pengaturan!$B$7)+Pengaturan!$B$8+AE11*Pengaturan!$B$9+AF11*Pengaturan!$B$10) | AN11: =IF(X11="","",N(G11)-AM11) | AO11: =IF(OR(X11="",N(G11)=0),"",AN11/G11)
R12: =IF(A12="","",N(G12)+N(I12)) | S12: =IF(OR(K12="",O12=""),"",O12-K12) | T12: =IF(AND(C12="Cetak",L12<>"",L12<TODAY()),"YA","") | U12: =IF(B12="","",TEXT(B12,"yyyy-mm")) | V12: =IF(K12="","",TEXT(K12,"yyyy-mm")) | W12: =IF(OR(C12="Cetak",C12="Dikirim",C12="Selesai"),1,0) -> 0 | X12: =IF(F12="","",SUBSTITUTE(SUBSTITUTE(MID(UPPER(TRIM(F12)),4,99),"-LED",""),"-TK","")) | Y12: =IF(X12="","",(LEN(X12)+1)/7) | Z12: =IF(X12="","",LEFT(X12,6)) | AA12: =IF(X12="","",IF(Y12>=3,MID(X12,8,6),"")) | AB12: =IF(X12="","",IF(Y12>=4,MID(X12,15,6),"")) | AC12: =IF(X12="","",IF(Y12>=5,MID(X12,22,6),"")) | AD12: =IF(X12="","",RIGHT(X12,6)) | AE12: =IF(F12="","",IF(ISNUMBER(SEARCH("-TK",UPPER(F12))),0,1)) | AF12: =IF(F12="","",IF(ISNUMBER(SEARCH("-LED",UPPER(F12))),1,0)) | AG12: =IF(Z12="",0,IFERROR(INDEX(Resep!$C$5:$C$7,MATCH(LEFT(Z12,3),Resep!$B$5:$B$7,0)),0)) -> 0 | AH12: =IF(AA12="",0,IFERROR(INDEX(Resep!$C$9:$C$13,MATCH(LEFT(AA12,3),Resep!$B$9:$B$13,0)),0)) -> 0 | AI12: =IF(AB12="",0,IFERROR(INDEX(Resep!$C$9:$C$13,MATCH(LEFT(AB12,3),Resep!$B$9:$B$13,0)),0)) -> 0 | AJ12: =IF(AC12="",0,IFERROR(INDEX(Resep!$C$9:$C$13,MATCH(LEFT(AC12,3),Resep!$B$9:$B$13,0)),0)) -> 0 | AK12: =IF(AD12="",0,IFERROR(INDEX(Resep!$C$15:$C$18,MATCH(LEFT(AD12,3),Resep!$B$15:$B$18,0)),0)) -> 0 | AL12: =IF(X12="","",AG12+AH12+AI12+AJ12+AK12) | AM12: =IF(X12="","",AL12*(Pengaturan!$B$6+Pengaturan!$B$7)+Pengaturan!$B$8+AE12*Pengaturan!$B$9+AF12*Pengaturan!$B$10) | AN12: =IF(X12="","",N(G12)-AM12) | AO12: =IF(OR(X12="",N(G12)=0),"",AN12/G12)
R13: =IF(A13="","",N(G13)+N(I13)) | S13: =IF(OR(K13="",O13=""),"",O13-K13) | T13: =IF(AND(C13="Cetak",L13<>"",L13<TODAY()),"YA","") | U13: =IF(B13="","",TEXT(B13,"yyyy-mm")) | V13: =IF(K13="","",TEXT(K13,"yyyy-mm")) | W13: =IF(OR(C13="Cetak",C13="Dikirim",C13="Selesai"),1,0) -> 0 | X13: =IF(F13="","",SUBSTITUTE(SUBSTITUTE(MID(UPPER(TRIM(F13)),4,99),"-LED",""),"-TK","")) | Y13: =IF(X13="","",(LEN(X13)+1)/7) | Z13: =IF(X13="","",LEFT(X13,6)) | AA13: =IF(X13="","",IF(Y13>=3,MID(X13,8,6),"")) | AB13: =IF(X13="","",IF(Y13>=4,MID(X13,15,6),"")) | AC13: =IF(X13="","",IF(Y13>=5,MID(X13,22,6),"")) | AD13: =IF(X13="","",RIGHT(X13,6)) | AE13: =IF(F13="","",IF(ISNUMBER(SEARCH("-TK",UPPER(F13))),0,1)) | AF13: =IF(F13="","",IF(ISNUMBER(SEARCH("-LED",UPPER(F13))),1,0)) | AG13: =IF(Z13="",0,IFERROR(INDEX(Resep!$C$5:$C$7,MATCH(LEFT(Z13,3),Resep!$B$5:$B$7,0)),0)) -> 0 | AH13: =IF(AA13="",0,IFERROR(INDEX(Resep!$C$9:$C$13,MATCH(LEFT(AA13,3),Resep!$B$9:$B$13,0)),0)) -> 0 | AI13: =IF(AB13="",0,IFERROR(INDEX(Resep!$C$9:$C$13,MATCH(LEFT(AB13,3),Resep!$B$9:$B$13,0)),0)) -> 0 | AJ13: =IF(AC13="",0,IFERROR(INDEX(Resep!$C$9:$C$13,MATCH(LEFT(AC13,3),Resep!$B$9:$B$13,0)),0)) -> 0 | AK13: =IF(AD13="",0,IFERROR(INDEX(Resep!$C$15:$C$18,MATCH(LEFT(AD13,3),Resep!$B$15:$B$18,0)),0)) -> 0 | AL13: =IF(X13="","",AG13+AH13+AI13+AJ13+AK13) | AM13: =IF(X13="","",AL13*(Pengaturan!$B$6+Pengaturan!$B$7)+Pengaturan!$B$8+AE13*Pengaturan!$B$9+AF13*Pengaturan!$B$10) | AN13: =IF(X13="","",N(G13)-AM13) | AO13: =IF(OR(X13="",N(G13)=0),"",AN13/G13)
R14: =IF(A14="","",N(G14)+N(I14)) | S14: =IF(OR(K14="",O14=""),"",O14-K14) | T14: =IF(AND(C14="Cetak",L14<>"",L14<TODAY()),"YA","") | U14: =IF(B14="","",TEXT(B14,"yyyy-mm")) | V14: =IF(K14="","",TEXT(K14,"yyyy-mm")) | W14: =IF(OR(C14="Cetak",C14="Dikirim",C14="Selesai"),1,0) -> 0 | X14: =IF(F14="","",SUBSTITUTE(SUBSTITUTE(MID(UPPER(TRIM(F14)),4,99),"-LED",""),"-TK","")) | Y14: =IF(X14="","",(LEN(X14)+1)/7) | Z14: =IF(X14="","",LEFT(X14,6)) | AA14: =IF(X14="","",IF(Y14>=3,MID(X14,8,6),"")) | AB14: =IF(X14="","",IF(Y14>=4,MID(X14,15,6),"")) | AC14: =IF(X14="","",IF(Y14>=5,MID(X14,22,6),"")) | AD14: =IF(X14="","",RIGHT(X14,6)) | AE14: =IF(F14="","",IF(ISNUMBER(SEARCH("-TK",UPPER(F14))),0,1)) | AF14: =IF(F14="","",IF(ISNUMBER(SEARCH("-LED",UPPER(F14))),1,0)) | AG14: =IF(Z14="",0,IFERROR(INDEX(Resep!$C$5:$C$7,MATCH(LEFT(Z14,3),Resep!$B$5:$B$7,0)),0)) -> 0 | AH14: =IF(AA14="",0,IFERROR(INDEX(Resep!$C$9:$C$13,MATCH(LEFT(AA14,3),Resep!$B$9:$B$13,0)),0)) -> 0 | AI14: =IF(AB14="",0,IFERROR(INDEX(Resep!$C$9:$C$13,MATCH(LEFT(AB14,3),Resep!$B$9:$B$13,0)),0)) -> 0 | AJ14: =IF(AC14="",0,IFERROR(INDEX(Resep!$C$9:$C$13,MATCH(LEFT(AC14,3),Resep!$B$9:$B$13,0)),0)) -> 0 | AK14: =IF(AD14="",0,IFERROR(INDEX(Resep!$C$15:$C$18,MATCH(LEFT(AD14,3),Resep!$B$15:$B$18,0)),0)) -> 0 | AL14: =IF(X14="","",AG14+AH14+AI14+AJ14+AK14) | AM14: =IF(X14="","",AL14*(Pengaturan!$B$6+Pengaturan!$B$7)+Pengaturan!$B$8+AE14*Pengaturan!$B$9+AF14*Pengaturan!$B$10) | AN14: =IF(X14="","",N(G14)-AM14) | AO14: =IF(OR(X14="",N(G14)=0),"",AN14/G14)
R15: =IF(A15="","",N(G15)+N(I15)) | S15: =IF(OR(K15="",O15=""),"",O15-K15) | T15: =IF(AND(C15="Cetak",L15<>"",L15<TODAY()),"YA","") | U15: =IF(B15="","",TEXT(B15,"yyyy-mm")) | V15: =IF(K15="","",TEXT(K15,"yyyy-mm")) | W15: =IF(OR(C15="Cetak",C15="Dikirim",C15="Selesai"),1,0) -> 0 | X15: =IF(F15="","",SUBSTITUTE(SUBSTITUTE(MID(UPPER(TRIM(F15)),4,99),"-LED",""),"-TK","")) | Y15: =IF(X15="","",(LEN(X15)+1)/7) | Z15: =IF(X15="","",LEFT(X15,6)) | AA15: =IF(X15="","",IF(Y15>=3,MID(X15,8,6),"")) | AB15: =IF(X15="","",IF(Y15>=4,MID(X15,15,6),"")) | AC15: =IF(X15="","",IF(Y15>=5,MID(X15,22,6),"")) | AD15: =IF(X15="","",RIGHT(X15,6)) | AE15: =IF(F15="","",IF(ISNUMBER(SEARCH("-TK",UPPER(F15))),0,1)) | AF15: =IF(F15="","",IF(ISNUMBER(SEARCH("-LED",UPPER(F15))),1,0)) | AG15: =IF(Z15="",0,IFERROR(INDEX(Resep!$C$5:$C$7,MATCH(LEFT(Z15,3),Resep!$B$5:$B$7,0)),0)) -> 0 | AH15: =IF(AA15="",0,IFERROR(INDEX(Resep!$C$9:$C$13,MATCH(LEFT(AA15,3),Resep!$B$9:$B$13,0)),0)) -> 0 | AI15: =IF(AB15="",0,IFERROR(INDEX(Resep!$C$9:$C$13,MATCH(LEFT(AB15,3),Resep!$B$9:$B$13,0)),0)) -> 0 | AJ15: =IF(AC15="",0,IFERROR(INDEX(Resep!$C$9:$C$13,MATCH(LEFT(AC15,3),Resep!$B$9:$B$13,0)),0)) -> 0 | AK15: =IF(AD15="",0,IFERROR(INDEX(Resep!$C$15:$C$18,MATCH(LEFT(AD15,3),Resep!$B$15:$B$18,0)),0)) -> 0 | AL15: =IF(X15="","",AG15+AH15+AI15+AJ15+AK15) | AM15: =IF(X15="","",AL15*(Pengaturan!$B$6+Pengaturan!$B$7)+Pengaturan!$B$8+AE15*Pengaturan!$B$9+AF15*Pengaturan!$B$10) | AN15: =IF(X15="","",N(G15)-AM15) | AO15: =IF(OR(X15="",N(G15)=0),"",AN15/G15)
R16: =IF(A16="","",N(G16)+N(I16)) | S16: =IF(OR(K16="",O16=""),"",O16-K16) | T16: =IF(AND(C16="Cetak",L16<>"",L16<TODAY()),"YA","") | U16: =IF(B16="","",TEXT(B16,"yyyy-mm")) | V16: =IF(K16="","",TEXT(K16,"yyyy-mm")) | W16: =IF(OR(C16="Cetak",C16="Dikirim",C16="Selesai"),1,0) -> 0 | X16: =IF(F16="","",SUBSTITUTE(SUBSTITUTE(MID(UPPER(TRIM(F16)),4,99),"-LED",""),"-TK","")) | Y16: =IF(X16="","",(LEN(X16)+1)/7) | Z16: =IF(X16="","",LEFT(X16,6)) | AA16: =IF(X16="","",IF(Y16>=3,MID(X16,8,6),"")) | AB16: =IF(X16="","",IF(Y16>=4,MID(X16,15,6),"")) | AC16: =IF(X16="","",IF(Y16>=5,MID(X16,22,6),"")) | AD16: =IF(X16="","",RIGHT(X16,6)) | AE16: =IF(F16="","",IF(ISNUMBER(SEARCH("-TK",UPPER(F16))),0,1)) | AF16: =IF(F16="","",IF(ISNUMBER(SEARCH("-LED",UPPER(F16))),1,0)) | AG16: =IF(Z16="",0,IFERROR(INDEX(Resep!$C$5:$C$7,MATCH(LEFT(Z16,3),Resep!$B$5:$B$7,0)),0)) -> 0 | AH16: =IF(AA16="",0,IFERROR(INDEX(Resep!$C$9:$C$13,MATCH(LEFT(AA16,3),Resep!$B$9:$B$13,0)),0)) -> 0 | AI16: =IF(AB16="",0,IFERROR(INDEX(Resep!$C$9:$C$13,MATCH(LEFT(AB16,3),Resep!$B$9:$B$13,0)),0)) -> 0 | AJ16: =IF(AC16="",0,IFERROR(INDEX(Resep!$C$9:$C$13,MATCH(LEFT(AC16,3),Resep!$B$9:$B$13,0)),0)) -> 0 | AK16: =IF(AD16="",0,IFERROR(INDEX(Resep!$C$15:$C$18,MATCH(LEFT(AD16,3),Resep!$B$15:$B$18,0)),0)) -> 0 | AL16: =IF(X16="","",AG16+AH16+AI16+AJ16+AK16) | AM16: =IF(X16="","",AL16*(Pengaturan!$B$6+Pengaturan!$B$7)+Pengaturan!$B$8+AE16*Pengaturan!$B$9+AF16*Pengaturan!$B$10) | AN16: =IF(X16="","",N(G16)-AM16) | AO16: =IF(OR(X16="",N(G16)=0),"",AN16/G16)
... R1000: =IF(A1000="","",N(G1000)+N(I1000)) | S1000: =IF(OR(K1000="",O1000=""),"",O1000-K1000) | T1000: =IF(AND(C1000="Cetak",L1000<>"",L1000<TODAY()),"YA","") | U1000: =IF(B1000="","",TEXT(B1000,"yyyy-mm")) | V1000: =IF(K1000="","",TEXT(K1000,"yyyy-mm")) | W1000: =IF(OR(C1000="Cetak",C1000="Dikirim",C1000="Selesai"),1,0) -> 0 | X1000: =IF(F1000="","",SUBSTITUTE(SUBSTITUTE(MID(UPPER(TRIM(F1000)),4,99),"-LED",""),"-TK","")) | Y1000: =IF(X1000="","",(LEN(X1000)+1)/7) | Z1000: =IF(X1000="","",LEFT(X1000,6)) | AA1000: =IF(X1000="","",IF(Y1000>=3,MID(X1000,8,6),"")) | AB1000: =IF(X1000="","",IF(Y1000>=4,MID(X1000,15,6),"")) | AC1000: =IF(X1000="","",IF(Y1000>=5,MID(X1000,22,6),"")) | AD1000: =IF(X1000="","",RIGHT(X1000,6)) | AE1000: =IF(F1000="","",IF(ISNUMBER(SEARCH("-TK",UPPER(F1000))),0,1)) | AF1000: =IF(F1000="","",IF(ISNUMBER(SEARCH("-LED",UPPER(F1000))),1,0)) | AG1000: =IF(Z1000="",0,IFERROR(INDEX(Resep!$C$5:$C$7,MATCH(LEFT(Z1000,3),Resep!$B$5:$B$7,0)),0)) -> 0 | AH1000: =IF(AA1000="",0,IFERROR(INDEX(Resep!$C$9:$C$13,MATCH(LEFT(AA1000,3),Resep!$B$9:$B$13,0)),0)) -> 0 | AI1000: =IF(AB1000="",0,IFERROR(INDEX(Resep!$C$9:$C$13,MATCH(LEFT(AB1000,3),Resep!$B$9:$B$13,0)),0)) -> 0 | AJ1000: =IF(AC1000="",0,IFERROR(INDEX(Resep!$C$9:$C$13,MATCH(LEFT(AC1000,3),Resep!$B$9:$B$13,0)),0)) -> 0 | AK1000: =IF(AD1000="",0,IFERROR(INDEX(Resep!$C$15:$C$18,MATCH(LEFT(AD1000,3),Resep!$B$15:$B$18,0)),0)) -> 0 | AL1000: =IF(X1000="","",AG1000+AH1000+AI1000+AJ1000+AK1000) | AM1000: =IF(X1000="","",AL1000*(Pengaturan!$B$6+Pengaturan!$B$7)+Pengaturan!$B$8+AE1000*Pengaturan!$B$9+AF1000*Pengaturan!$B$10) | AN1000: =IF(X1000="","",N(G1000)-AM1000) | AO1000: =IF(OR(X1000="",N(G1000)=0),"",AN1000/G1000)

Sheet Stok filamen
A1: Stok filamen (gram)
A2: Masuk/Koreksi/Pakai manual dari tab Mutasi stok. Pakai otomatis = pesanan berstatus Cetak/Dikirim/Selesai × gram di tab Resep.
A4: Kode | B4: Warna | C4: Dipakai di | D4: Merek / SKU | E4: Masuk (g) | F4: Koreksi (g) | G4: Pakai otomatis (g) | H4: Pakai manual (g) | I4: Sisa (g) | J4: Sisa roll | K4: Pakai 30 hari (g) | L4: Hari tersisa | M4: Status | N4: No. peringatan
A5: KRE | B5: Krem | C5: Badan/Alas | E5: =SUMIFS('Mutasi stok'!$E$2:$E$2000,'Mutasi stok'!$B$2:$B$2000,"Masuk",'Mutasi stok'!$C$2:$C$2000,"Filamen",'Mutasi stok'!$D$2:$D$2000,$A5) -> 1000 | F5: =SUMIFS('Mutasi stok'!$E$2:$E$2000,'Mutasi stok'!$B$2:$B$2000,"Koreksi",'Mutasi stok'!$C$2:$C$2000,"Filamen",'Mutasi stok'!$D$2:$D$2000,$A5) -> 0 | G5: =SUMPRODUCT(Pesanan!$W$2:$W$1000*((RIGHT(Pesanan!$Z$2:$Z$1000,3)=$A5)*Pesanan!$AG$2:$AG$1000+(RIGHT(Pesanan!$AA$2:$AA$1000,3)=$A5)*Pesanan!$AH$2:$AH$1000+(RIGHT(Pesanan!$AB$2:$AB$1000,3)=$A5)*Pesanan!$AI$2:$AI$1000+(RIGHT(Pesanan!$AC$2:$AC$1000,3)=$A5)*Pesanan!$AJ$2:$AJ$1000+(RIGHT(Pesanan!$AD$2:$AD$1000,3)=$A5)*Pesanan!$AK$2:$AK$1000)) -> 190 | H5: =SUMIFS('Mutasi stok'!$E$2:$E$2000,'Mutasi stok'!$B$2:$B$2000,"Pakai",'Mutasi stok'!$C$2:$C$2000,"Filamen",'Mutasi stok'!$D$2:$D$2000,$A5) -> 0 | I5: =E5+F5-G5-H5 -> 810 | J5: =IF(Pengaturan!$B$14=0,"",I5/Pengaturan!$B$14) -> 0.81 | K5: =SUMPRODUCT(Pesanan!$W$2:$W$1000*(Pesanan!$K$2:$K$1000>=TODAY()-30)*((RIGHT(Pesanan!$Z$2:$Z$1000,3)=$A5)*Pesanan!$AG$2:$AG$1000+(RIGHT(Pesanan!$AA$2:$AA$1000,3)=$A5)*Pesanan!$AH$2:$AH$1000+(RIGHT(Pesanan!$AB$2:$AB$1000,3)=$A5)*Pesanan!$AI$2:$AI$1000+(RIGHT(Pesanan!$AC$2:$AC$1000,3)=$A5)*Pesanan!$AJ$2:$AJ$1000+(RIGHT(Pesanan!$AD$2:$AD$1000,3)=$A5)*Pesanan!$AK$2:$AK$1000))+SUMIFS('Mutasi stok'!$E$2:$E$2000,'Mutasi stok'!$B$2:$B$2000,"Pakai",'Mutasi stok'!$C$2:$C$2000,"Filamen",'Mutasi stok'!$D$2:$D$2000,$A5,'Mutasi stok'!$A$2:$A$2000,">="&(TODAY()-30)) -> 0 | L5: =IF(K5<=0,"",ROUND(I5/(K5/30),0)) | M5: =IF(I5<Pengaturan!$B$13,"PESAN","OK") -> OK | N5: =IF(M5="PESAN",COUNTIF($M$5:M5,"PESAN"),"")
A6: HIT | B6: Hitam arang | C6: Badan/Alas | E6: =SUMIFS('Mutasi stok'!$E$2:$E$2000,'Mutasi stok'!$B$2:$B$2000,"Masuk",'Mutasi stok'!$C$2:$C$2000,"Filamen",'Mutasi stok'!$D$2:$D$2000,$A6) -> 1000 | F6: =SUMIFS('Mutasi stok'!$E$2:$E$2000,'Mutasi stok'!$B$2:$B$2000,"Koreksi",'Mutasi stok'!$C$2:$C$2000,"Filamen",'Mutasi stok'!$D$2:$D$2000,$A6) -> 0 | G6: =SUMPRODUCT(Pesanan!$W$2:$W$1000*((RIGHT(Pesanan!$Z$2:$Z$1000,3)=$A6)*Pesanan!$AG$2:$AG$1000+(RIGHT(Pesanan!$AA$2:$AA$1000,3)=$A6)*Pesanan!$AH$2:$AH$1000+(RIGHT(Pesanan!$AB$2:$AB$1000,3)=$A6)*Pesanan!$AI$2:$AI$1000+(RIGHT(Pesanan!$AC$2:$AC$1000,3)=$A6)*Pesanan!$AJ$2:$AJ$1000+(RIGHT(Pesanan!$AD$2:$AD$1000,3)=$A6)*Pesanan!$AK$2:$AK$1000)) -> 220 | H6: =SUMIFS('Mutasi stok'!$E$2:$E$2000,'Mutasi stok'!$B$2:$B$2000,"Pakai",'Mutasi stok'!$C$2:$C$2000,"Filamen",'Mutasi stok'!$D$2:$D$2000,$A6) -> 0 | I6: =E6+F6-G6-H6 -> 780 | J6: =IF(Pengaturan!$B$14=0,"",I6/Pengaturan!$B$14) -> 0.78 | K6: =SUMPRODUCT(Pesanan!$W$2:$W$1000*(Pesanan!$K$2:$K$1000>=TODAY()-30)*((RIGHT(Pesanan!$Z$2:$Z$1000,3)=$A6)*Pesanan!$AG$2:$AG$1000+(RIGHT(Pesanan!$AA$2:$AA$1000,3)=$A6)*Pesanan!$AH$2:$AH$1000+(RIGHT(Pesanan!$AB$2:$AB$1000,3)=$A6)*Pesanan!$AI$2:$AI$1000+(RIGHT(Pesanan!$AC$2:$AC$1000,3)=$A6)*Pesanan!$AJ$2:$AJ$1000+(RIGHT(Pesanan!$AD$2:$AD$1000,3)=$A6)*Pesanan!$AK$2:$AK$1000))+SUMIFS('Mutasi stok'!$E$2:$E$2000,'Mutasi stok'!$B$2:$B$2000,"Pakai",'Mutasi stok'!$C$2:$C$2000,"Filamen",'Mutasi stok'!$D$2:$D$2000,$A6,'Mutasi stok'!$A$2:$A$2000,">="&(TODAY()-30)) -> 0 | L6: =IF(K6<=0,"",ROUND(I6/(K6/30),0)) | M6: =IF(I6<Pengaturan!$B$13,"PESAN","OK") -> OK | N6: =IF(M6="PESAN",COUNTIF($M$5:M6,"PESAN"),"")
A7: BAT | B7: Merah bata | C7: Badan/Alas | E7: =SUMIFS('Mutasi stok'!$E$2:$E$2000,'Mutasi stok'!$B$2:$B$2000,"Masuk",'Mutasi stok'!$C$2:$C$2000,"Filamen",'Mutasi stok'!$D$2:$D$2000,$A7) -> 1000 | F7: =SUMIFS('Mutasi stok'!$E$2:$E$2000,'Mutasi stok'!$B$2:$B$2000,"Koreksi",'Mutasi stok'!$C$2:$C$2000,"Filamen",'Mutasi stok'!$D$2:$D$2000,$A7) -> 0 | G7: =SUMPRODUCT(Pesanan!$W$2:$W$1000*((RIGHT(Pesanan!$Z$2:$Z$1000,3)=$A7)*Pesanan!$AG$2:$AG$1000+(RIGHT(Pesanan!$AA$2:$AA$1000,3)=$A7)*Pesanan!$AH$2:$AH$1000+(RIGHT(Pesanan!$AB$2:$AB$1000,3)=$A7)*Pesanan!$AI$2:$AI$1000+(RIGHT(Pesanan!$AC$2:$AC$1000,3)=$A7)*Pesanan!$AJ$2:$AJ$1000+(RIGHT(Pesanan!$AD$2:$AD$1000,3)=$A7)*Pesanan!$AK$2:$AK$1000)) -> 390 | H7: =SUMIFS('Mutasi stok'!$E$2:$E$2000,'Mutasi stok'!$B$2:$B$2000,"Pakai",'Mutasi stok'!$C$2:$C$2000,"Filamen",'Mutasi stok'!$D$2:$D$2000,$A7) -> 90 | I7: =E7+F7-G7-H7 -> 520 | J7: =IF(Pengaturan!$B$14=0,"",I7/Pengaturan!$B$14) -> 0.52 | K7: =SUMPRODUCT(Pesanan!$W$2:$W$1000*(Pesanan!$K$2:$K$1000>=TODAY()-30)*((RIGHT(Pesanan!$Z$2:$Z$1000,3)=$A7)*Pesanan!$AG$2:$AG$1000+(RIGHT(Pesanan!$AA$2:$AA$1000,3)=$A7)*Pesanan!$AH$2:$AH$1000+(RIGHT(Pesanan!$AB$2:$AB$1000,3)=$A7)*Pesanan!$AI$2:$AI$1000+(RIGHT(Pesanan!$AC$2:$AC$1000,3)=$A7)*Pesanan!$AJ$2:$AJ$1000+(RIGHT(Pesanan!$AD$2:$AD$1000,3)=$A7)*Pesanan!$AK$2:$AK$1000))+SUMIFS('Mutasi stok'!$E$2:$E$2000,'Mutasi stok'!$B$2:$B$2000,"Pakai",'Mutasi stok'!$C$2:$C$2000,"Filamen",'Mutasi stok'!$D$2:$D$2000,$A7,'Mutasi stok'!$A$2:$A$2000,">="&(TODAY()-30)) -> 0 | L7: =IF(K7<=0,"",ROUND(I7/(K7/30),0)) | M7: =IF(I7<Pengaturan!$B$13,"PESAN","OK") -> OK | N7: =IF(M7="PESAN",COUNTIF($M$5:M7,"PESAN"),"")
A8: ZAI | B8: Zaitun | C8: Badan/Alas | E8: =SUMIFS('Mutasi stok'!$E$2:$E$2000,'Mutasi stok'!$B$2:$B$2000,"Masuk",'Mutasi stok'!$C$2:$C$2000,"Filamen",'Mutasi stok'!$D$2:$D$2000,$A8) -> 1000 | F8: =SUMIFS('Mutasi stok'!$E$2:$E$2000,'Mutasi stok'!$B$2:$B$2000,"Koreksi",'Mutasi stok'!$C$2:$C$2000,"Filamen",'Mutasi stok'!$D$2:$D$2000,$A8) -> 0 | G8: =SUMPRODUCT(Pesanan!$W$2:$W$1000*((RIGHT(Pesanan!$Z$2:$Z$1000,3)=$A8)*Pesanan!$AG$2:$AG$1000+(RIGHT(Pesanan!$AA$2:$AA$1000,3)=$A8)*Pesanan!$AH$2:$AH$1000+(RIGHT(Pesanan!$AB$2:$AB$1000,3)=$A8)*Pesanan!$AI$2:$AI$1000+(RIGHT(Pesanan!$AC$2:$AC$1000,3)=$A8)*Pesanan!$AJ$2:$AJ$1000+(RIGHT(Pesanan!$AD$2:$AD$1000,3)=$A8)*Pesanan!$AK$2:$AK$1000)) -> 180 | H8: =SUMIFS('Mutasi stok'!$E$2:$E$2000,'Mutasi stok'!$B$2:$B$2000,"Pakai",'Mutasi stok'!$C$2:$C$2000,"Filamen",'Mutasi stok'!$D$2:$D$2000,$A8) -> 0 | I8: =E8+F8-G8-H8 -> 820 | J8: =IF(Pengaturan!$B$14=0,"",I8/Pengaturan!$B$14) -> 0.82 | K8: =SUMPRODUCT(Pesanan!$W$2:$W$1000*(Pesanan!$K$2:$K$1000>=TODAY()-30)*((RIGHT(Pesanan!$Z$2:$Z$1000,3)=$A8)*Pesanan!$AG$2:$AG$1000+(RIGHT(Pesanan!$AA$2:$AA$1000,3)=$A8)*Pesanan!$AH$2:$AH$1000+(RIGHT(Pesanan!$AB$2:$AB$1000,3)=$A8)*Pesanan!$AI$2:$AI$1000+(RIGHT(Pesanan!$AC$2:$AC$1000,3)=$A8)*Pesanan!$AJ$2:$AJ$1000+(RIGHT(Pesanan!$AD$2:$AD$1000,3)=$A8)*Pesanan!$AK$2:$AK$1000))+SUMIFS('Mutasi stok'!$E$2:$E$2000,'Mutasi stok'!$B$2:$B$2000,"Pakai",'Mutasi stok'!$C$2:$C$2000,"Filamen",'Mutasi stok'!$D$2:$D$2000,$A8,'Mutasi stok'!$A$2:$A$2000,">="&(TODAY()-30)) -> 0 | L8: =IF(K8<=0,"",ROUND(I8/(K8/30),0)) | M8: =IF(I8<Pengaturan!$B$13,"PESAN","OK") -> OK | N8: =IF(M8="PESAN",COUNTIF($M$5:M8,"PESAN"),"")
A9: SAL | B9: Salmon | C9: Badan/Alas | E9: =SUMIFS('Mutasi stok'!$E$2:$E$2000,'Mutasi stok'!$B$2:$B$2000,"Masuk",'Mutasi stok'!$C$2:$C$2000,"Filamen",'Mutasi stok'!$D$2:$D$2000,$A9) -> 1000 | F9: =SUMIFS('Mutasi stok'!$E$2:$E$2000,'Mutasi stok'!$B$2:$B$2000,"Koreksi",'Mutasi stok'!$C$2:$C$2000,"Filamen",'Mutasi stok'!$D$2:$D$2000,$A9) -> 0 | G9: =SUMPRODUCT(Pesanan!$W$2:$W$1000*((RIGHT(Pesanan!$Z$2:$Z$1000,3)=$A9)*Pesanan!$AG$2:$AG$1000+(RIGHT(Pesanan!$AA$2:$AA$1000,3)=$A9)*Pesanan!$AH$2:$AH$1000+(RIGHT(Pesanan!$AB$2:$AB$1000,3)=$A9)*Pesanan!$AI$2:$AI$1000+(RIGHT(Pesanan!$AC$2:$AC$1000,3)=$A9)*Pesanan!$AJ$2:$AJ$1000+(RIGHT(Pesanan!$AD$2:$AD$1000,3)=$A9)*Pesanan!$AK$2:$AK$1000)) -> 180 | H9: =SUMIFS('Mutasi stok'!$E$2:$E$2000,'Mutasi stok'!$B$2:$B$2000,"Pakai",'Mutasi stok'!$C$2:$C$2000,"Filamen",'Mutasi stok'!$D$2:$D$2000,$A9) -> 0 | I9: =E9+F9-G9-H9 -> 820 | J9: =IF(Pengaturan!$B$14=0,"",I9/Pengaturan!$B$14) -> 0.82 | K9: =SUMPRODUCT(Pesanan!$W$2:$W$1000*(Pesanan!$K$2:$K$1000>=TODAY()-30)*((RIGHT(Pesanan!$Z$2:$Z$1000,3)=$A9)*Pesanan!$AG$2:$AG$1000+(RIGHT(Pesanan!$AA$2:$AA$1000,3)=$A9)*Pesanan!$AH$2:$AH$1000+(RIGHT(Pesanan!$AB$2:$AB$1000,3)=$A9)*Pesanan!$AI$2:$AI$1000+(RIGHT(Pesanan!$AC$2:$AC$1000,3)=$A9)*Pesanan!$AJ$2:$AJ$1000+(RIGHT(Pesanan!$AD$2:$AD$1000,3)=$A9)*Pesanan!$AK$2:$AK$1000))+SUMIFS('Mutasi stok'!$E$2:$E$2000,'Mutasi stok'!$B$2:$B$2000,"Pakai",'Mutasi stok'!$C$2:$C$2000,"Filamen",'Mutasi stok'!$D$2:$D$2000,$A9,'Mutasi stok'!$A$2:$A$2000,">="&(TODAY()-30)) -> 0 | L9: =IF(K9<=0,"",ROUND(I9/(K9/30),0)) | M9: =IF(I9<Pengaturan!$B$13,"PESAN","OK") -> OK | N9: =IF(M9="PESAN",COUNTIF($M$5:M9,"PESAN"),"")
A10: GAD | B10: Gading | C10: Kap | E10: =SUMIFS('Mutasi stok'!$E$2:$E$2000,'Mutasi stok'!$B$2:$B$2000,"Masuk",'Mutasi stok'!$C$2:$C$2000,"Filamen",'Mutasi stok'!$D$2:$D$2000,$A10) -> 1000 | F10: =SUMIFS('Mutasi stok'!$E$2:$E$2000,'Mutasi stok'!$B$2:$B$2000,"Koreksi",'Mutasi stok'!$C$2:$C$2000,"Filamen",'Mutasi stok'!$D$2:$D$2000,$A10) -> 0 | G10: =SUMPRODUCT(Pesanan!$W$2:$W$1000*((RIGHT(Pesanan!$Z$2:$Z$1000,3)=$A10)*Pesanan!$AG$2:$AG$1000+(RIGHT(Pesanan!$AA$2:$AA$1000,3)=$A10)*Pesanan!$AH$2:$AH$1000+(RIGHT(Pesanan!$AB$2:$AB$1000,3)=$A10)*Pesanan!$AI$2:$AI$1000+(RIGHT(Pesanan!$AC$2:$AC$1000,3)=$A10)*Pesanan!$AJ$2:$AJ$1000+(RIGHT(Pesanan!$AD$2:$AD$1000,3)=$A10)*Pesanan!$AK$2:$AK$1000)) -> 370 | H10: =SUMIFS('Mutasi stok'!$E$2:$E$2000,'Mutasi stok'!$B$2:$B$2000,"Pakai",'Mutasi stok'!$C$2:$C$2000,"Filamen",'Mutasi stok'!$D$2:$D$2000,$A10) -> 0 | I10: =E10+F10-G10-H10 -> 630 | J10: =IF(Pengaturan!$B$14=0,"",I10/Pengaturan!$B$14) -> 0.63 | K10: =SUMPRODUCT(Pesanan!$W$2:$W$1000*(Pesanan!$K$2:$K$1000>=TODAY()-30)*((RIGHT(Pesanan!$Z$2:$Z$1000,3)=$A10)*Pesanan!$AG$2:$AG$1000+(RIGHT(Pesanan!$AA$2:$AA$1000,3)=$A10)*Pesanan!$AH$2:$AH$1000+(RIGHT(Pesanan!$AB$2:$AB$1000,3)=$A10)*Pesanan!$AI$2:$AI$1000+(RIGHT(Pesanan!$AC$2:$AC$1000,3)=$A10)*Pesanan!$AJ$2:$AJ$1000+(RIGHT(Pesanan!$AD$2:$AD$1000,3)=$A10)*Pesanan!$AK$2:$AK$1000))+SUMIFS('Mutasi stok'!$E$2:$E$2000,'Mutasi stok'!$B$2:$B$2000,"Pakai",'Mutasi stok'!$C$2:$C$2000,"Filamen",'Mutasi stok'!$D$2:$D$2000,$A10,'Mutasi stok'!$A$2:$A$2000,">="&(TODAY()-30)) -> 0 | L10: =IF(K10<=0,"",ROUND(I10/(K10/30),0)) | M10: =IF(I10<Pengaturan!$B$13,"PESAN","OK") -> OK | N10: =IF(M10="PESAN",COUNTIF($M$5:M10,"PESAN"),"")
A11: PUT | B11: Putih | C11: Kap | E11: =SUMIFS('Mutasi stok'!$E$2:$E$2000,'Mutasi stok'!$B$2:$B$2000,"Masuk",'Mutasi stok'!$C$2:$C$2000,"Filamen",'Mutasi stok'!$D$2:$D$2000,$A11) -> 1000 | F11: =SUMIFS('Mutasi stok'!$E$2:$E$2000,'Mutasi stok'!$B$2:$B$2000,"Koreksi",'Mutasi stok'!$C$2:$C$2000,"Filamen",'Mutasi stok'!$D$2:$D$2000,$A11) -> 0 | G11: =SUMPRODUCT(Pesanan!$W$2:$W$1000*((RIGHT(Pesanan!$Z$2:$Z$1000,3)=$A11)*Pesanan!$AG$2:$AG$1000+(RIGHT(Pesanan!$AA$2:$AA$1000,3)=$A11)*Pesanan!$AH$2:$AH$1000+(RIGHT(Pesanan!$AB$2:$AB$1000,3)=$A11)*Pesanan!$AI$2:$AI$1000+(RIGHT(Pesanan!$AC$2:$AC$1000,3)=$A11)*Pesanan!$AJ$2:$AJ$1000+(RIGHT(Pesanan!$AD$2:$AD$1000,3)=$A11)*Pesanan!$AK$2:$AK$1000)) -> 0 | H11: =SUMIFS('Mutasi stok'!$E$2:$E$2000,'Mutasi stok'!$B$2:$B$2000,"Pakai",'Mutasi stok'!$C$2:$C$2000,"Filamen",'Mutasi stok'!$D$2:$D$2000,$A11) -> 0 | I11: =E11+F11-G11-H11 -> 1000 | J11: =IF(Pengaturan!$B$14=0,"",I11/Pengaturan!$B$14) -> 1 | K11: =SUMPRODUCT(Pesanan!$W$2:$W$1000*(Pesanan!$K$2:$K$1000>=TODAY()-30)*((RIGHT(Pesanan!$Z$2:$Z$1000,3)=$A11)*Pesanan!$AG$2:$AG$1000+(RIGHT(Pesanan!$AA$2:$AA$1000,3)=$A11)*Pesanan!$AH$2:$AH$1000+(RIGHT(Pesanan!$AB$2:$AB$1000,3)=$A11)*Pesanan!$AI$2:$AI$1000+(RIGHT(Pesanan!$AC$2:$AC$1000,3)=$A11)*Pesanan!$AJ$2:$AJ$1000+(RIGHT(Pesanan!$AD$2:$AD$1000,3)=$A11)*Pesanan!$AK$2:$AK$1000))+SUMIFS('Mutasi stok'!$E$2:$E$2000,'Mutasi stok'!$B$2:$B$2000,"Pakai",'Mutasi stok'!$C$2:$C$2000,"Filamen",'Mutasi stok'!$D$2:$D$2000,$A11,'Mutasi stok'!$A$2:$A$2000,">="&(TODAY()-30)) -> 0 | L11: =IF(K11<=0,"",ROUND(I11/(K11/30),0)) | M11: =IF(I11<Pengaturan!$B$13,"PESAN","OK") -> OK | N11: =IF(M11="PESAN",COUNTIF($M$5:M11,"PESAN"),"")
A13: Tambah warna baru: sisipkan baris di dalam tabel (klik kanan baris terakhir → sisipkan), salin rumus dari baris di atasnya, isi Kode 3 huruf sesuai id di lamp-data.js, dan tambahkan kodenya di tab Resep.
A14: Opname bulanan: timbang tiap roll (gram bersih = berat roll − berat spool kosong ±200 g), lalu catat selisihnya di Mutasi stok sebagai Koreksi.
A16: Kuning = diisi manual | B16: Abu-abu = rumus, jangan diketik

Sheet Stok bahan
A1: Stok bahan: kemasan & kelistrikan
A2: Masuk/Koreksi/Pakai manual dari Mutasi stok (Kategori = Bahan, Item harus sama persis). Pakai otomatis dihitung per pesanan terbayar.
A4: Item | B4: Satuan | C4: Dasar pemakaian | D4: Jumlah per pesanan | E4: Masuk | F4: Koreksi | G4: Pakai otomatis | H4: Pakai manual | I4: Sisa | J4: Minimum | K4: Status | L4: Supplier / catatan | M4: Harga satuan terakhir | N4: No. peringatan | O4: Baris Mutasi terakhir
A5: Dus kraft 240×240×200 | B5: pcs | C5: Per pesanan | D5: 1 | E5: =SUMIFS('Mutasi stok'!$E$2:$E$2000,'Mutasi stok'!$B$2:$B$2000,"Masuk",'Mutasi stok'!$C$2:$C$2000,"Bahan",'Mutasi stok'!$D$2:$D$2000,$A5) -> 50 | F5: =SUMIFS('Mutasi stok'!$E$2:$E$2000,'Mutasi stok'!$B$2:$B$2000,"Koreksi",'Mutasi stok'!$C$2:$C$2000,"Bahan",'Mutasi stok'!$D$2:$D$2000,$A5) -> 0 | G5: =IF(C5="Per pesanan",D5*SUMPRODUCT(Pesanan!$W$2:$W$1000),IF(C5="Per kit",D5*SUMPRODUCT(Pesanan!$W$2:$W$1000*(Pesanan!$AE$2:$AE$1000=1)),IF(C5="Per LED",D5*SUMPRODUCT(Pesanan!$W$2:$W$1000*(Pesanan!$AF$2:$AF$1000=1)),0))) -> 2 | H5: =SUMIFS('Mutasi stok'!$E$2:$E$2000,'Mutasi stok'!$B$2:$B$2000,"Pakai",'Mutasi stok'!$C$2:$C$2000,"Bahan",'Mutasi stok'!$D$2:$D$2000,$A5) -> 0 | I5: =E5+F5-G5-H5 -> 48 | J5: 20 | K5: =IF(I5<J5,"PESAN","OK") -> OK | L5: Percetakan dus, MOQ 300–500; lihat ops/kemasan.md | M5: =IF(O5=0,"",INDEX('Mutasi stok'!$G$2:$G$2000,O5)/INDEX('Mutasi stok'!$E$2:$E$2000,O5)) -> 12000 | N5: =IF(K5="PESAN",COUNTIF($K$5:K5,"PESAN"),"") | O5: =SUMPRODUCT(MAX(('Mutasi stok'!$D$2:$D$2000=$A5)*('Mutasi stok'!$B$2:$B$2000="Masuk")*('Mutasi stok'!$G$2:$G$2000>0)*(ROW('Mutasi stok'!$D$2:$D$2000)-1))) -> 9
A6: Insert E-flute | B6: set | C6: Per pesanan | D6: 1 | E6: =SUMIFS('Mutasi stok'!$E$2:$E$2000,'Mutasi stok'!$B$2:$B$2000,"Masuk",'Mutasi stok'!$C$2:$C$2000,"Bahan",'Mutasi stok'!$D$2:$D$2000,$A6) -> 50 | F6: =SUMIFS('Mutasi stok'!$E$2:$E$2000,'Mutasi stok'!$B$2:$B$2000,"Koreksi",'Mutasi stok'!$C$2:$C$2000,"Bahan",'Mutasi stok'!$D$2:$D$2000,$A6) -> 0 | G6: =IF(C6="Per pesanan",D6*SUMPRODUCT(Pesanan!$W$2:$W$1000),IF(C6="Per kit",D6*SUMPRODUCT(Pesanan!$W$2:$W$1000*(Pesanan!$AE$2:$AE$1000=1)),IF(C6="Per LED",D6*SUMPRODUCT(Pesanan!$W$2:$W$1000*(Pesanan!$AF$2:$AF$1000=1)),0))) -> 2 | H6: =SUMIFS('Mutasi stok'!$E$2:$E$2000,'Mutasi stok'!$B$2:$B$2000,"Pakai",'Mutasi stok'!$C$2:$C$2000,"Bahan",'Mutasi stok'!$D$2:$D$2000,$A6) -> 0 | I6: =E6+F6-G6-H6 -> 48 | J6: 20 | K6: =IF(I6<J6,"PESAN","OK") -> OK | L6: Satu set = nampan dasar + pemisah + cradle | M6: =IF(O6=0,"",INDEX('Mutasi stok'!$G$2:$G$2000,O6)/INDEX('Mutasi stok'!$E$2:$E$2000,O6)) -> 4000 | N6: =IF(K6="PESAN",COUNTIF($K$5:K6,"PESAN"),"") | O6: =SUMPRODUCT(MAX(('Mutasi stok'!$D$2:$D$2000=$A6)*('Mutasi stok'!$B$2:$B$2000="Masuk")*('Mutasi stok'!$G$2:$G$2000>0)*(ROW('Mutasi stok'!$D$2:$D$2000)-1))) -> 10
A7: Stiker kode rakitan | B7: pcs | C7: Per pesanan | D7: 1 | E7: =SUMIFS('Mutasi stok'!$E$2:$E$2000,'Mutasi stok'!$B$2:$B$2000,"Masuk",'Mutasi stok'!$C$2:$C$2000,"Bahan",'Mutasi stok'!$D$2:$D$2000,$A7) -> 100 | F7: =SUMIFS('Mutasi stok'!$E$2:$E$2000,'Mutasi stok'!$B$2:$B$2000,"Koreksi",'Mutasi stok'!$C$2:$C$2000,"Bahan",'Mutasi stok'!$D$2:$D$2000,$A7) -> 0 | G7: =IF(C7="Per pesanan",D7*SUMPRODUCT(Pesanan!$W$2:$W$1000),IF(C7="Per kit",D7*SUMPRODUCT(Pesanan!$W$2:$W$1000*(Pesanan!$AE$2:$AE$1000=1)),IF(C7="Per LED",D7*SUMPRODUCT(Pesanan!$W$2:$W$1000*(Pesanan!$AF$2:$AF$1000=1)),0))) -> 2 | H7: =SUMIFS('Mutasi stok'!$E$2:$E$2000,'Mutasi stok'!$B$2:$B$2000,"Pakai",'Mutasi stok'!$C$2:$C$2000,"Bahan",'Mutasi stok'!$D$2:$D$2000,$A7) -> 0 | I7: =E7+F7-G7-H7 -> 98 | J7: 30 | K7: =IF(I7<J7,"PESAN","OK") -> OK | L7: Cetak digital/thermal 80×48 mm | M7: =IF(O7=0,"",INDEX('Mutasi stok'!$G$2:$G$2000,O7)/INDEX('Mutasi stok'!$E$2:$E$2000,O7)) -> 600 | N7: =IF(K7="PESAN",COUNTIF($K$5:K7,"PESAN"),"") | O7: =SUMPRODUCT(MAX(('Mutasi stok'!$D$2:$D$2000=$A7)*('Mutasi stok'!$B$2:$B$2000="Masuk")*('Mutasi stok'!$G$2:$G$2000>0)*(ROW('Mutasi stok'!$D$2:$D$2000)-1))) -> 13
A8: Tisu kraft | B8: lembar | C8: Per pesanan | D8: 5 | E8: =SUMIFS('Mutasi stok'!$E$2:$E$2000,'Mutasi stok'!$B$2:$B$2000,"Masuk",'Mutasi stok'!$C$2:$C$2000,"Bahan",'Mutasi stok'!$D$2:$D$2000,$A8) -> 100 | F8: =SUMIFS('Mutasi stok'!$E$2:$E$2000,'Mutasi stok'!$B$2:$B$2000,"Koreksi",'Mutasi stok'!$C$2:$C$2000,"Bahan",'Mutasi stok'!$D$2:$D$2000,$A8) -> 0 | G8: =IF(C8="Per pesanan",D8*SUMPRODUCT(Pesanan!$W$2:$W$1000),IF(C8="Per kit",D8*SUMPRODUCT(Pesanan!$W$2:$W$1000*(Pesanan!$AE$2:$AE$1000=1)),IF(C8="Per LED",D8*SUMPRODUCT(Pesanan!$W$2:$W$1000*(Pesanan!$AF$2:$AF$1000=1)),0))) -> 10 | H8: =SUMIFS('Mutasi stok'!$E$2:$E$2000,'Mutasi stok'!$B$2:$B$2000,"Pakai",'Mutasi stok'!$C$2:$C$2000,"Bahan",'Mutasi stok'!$D$2:$D$2000,$A8) -> 0 | I8: =E8+F8-G8-H8 -> 90 | J8: 50 | K8: =IF(I8<J8,"PESAN","OK") -> OK | L8: 5 lembar per pesanan (tiap bagian dibungkus) | M8: =IF(O8=0,"",INDEX('Mutasi stok'!$G$2:$G$2000,O8)/INDEX('Mutasi stok'!$E$2:$E$2000,O8)) -> 500 | N8: =IF(K8="PESAN",COUNTIF($K$5:K8,"PESAN"),"") | O8: =SUMPRODUCT(MAX(('Mutasi stok'!$D$2:$D$2000=$A8)*('Mutasi stok'!$B$2:$B$2000="Masuk")*('Mutasi stok'!$G$2:$G$2000>0)*(ROW('Mutasi stok'!$D$2:$D$2000)-1))) -> 14
A9: Bubble wrap | B9: m | C9: Per pesanan | D9: 1.5 | E9: =SUMIFS('Mutasi stok'!$E$2:$E$2000,'Mutasi stok'!$B$2:$B$2000,"Masuk",'Mutasi stok'!$C$2:$C$2000,"Bahan",'Mutasi stok'!$D$2:$D$2000,$A9) -> 20 | F9: =SUMIFS('Mutasi stok'!$E$2:$E$2000,'Mutasi stok'!$B$2:$B$2000,"Koreksi",'Mutasi stok'!$C$2:$C$2000,"Bahan",'Mutasi stok'!$D$2:$D$2000,$A9) -> 0 | G9: =IF(C9="Per pesanan",D9*SUMPRODUCT(Pesanan!$W$2:$W$1000),IF(C9="Per kit",D9*SUMPRODUCT(Pesanan!$W$2:$W$1000*(Pesanan!$AE$2:$AE$1000=1)),IF(C9="Per LED",D9*SUMPRODUCT(Pesanan!$W$2:$W$1000*(Pesanan!$AF$2:$AF$1000=1)),0))) -> 3 | H9: =SUMIFS('Mutasi stok'!$E$2:$E$2000,'Mutasi stok'!$B$2:$B$2000,"Pakai",'Mutasi stok'!$C$2:$C$2000,"Bahan",'Mutasi stok'!$D$2:$D$2000,$A9) -> 0 | I9: =E9+F9-G9-H9 -> 17 | J9: 10 | K9: =IF(I9<J9,"PESAN","OK") -> OK | L9: ±1,5 m per dus | M9: =IF(O9=0,"",INDEX('Mutasi stok'!$G$2:$G$2000,O9)/INDEX('Mutasi stok'!$E$2:$E$2000,O9)) -> 3000 | N9: =IF(K9="PESAN",COUNTIF($K$5:K9,"PESAN"),"") | O9: =SUMPRODUCT(MAX(('Mutasi stok'!$D$2:$D$2000=$A9)*('Mutasi stok'!$B$2:$B$2000="Masuk")*('Mutasi stok'!$G$2:$G$2000>0)*(ROW('Mutasi stok'!$D$2:$D$2000)-1))) -> 15
A10: Kit kelistrikan | B10: pcs | C10: Per kit | D10: 1 | E10: =SUMIFS('Mutasi stok'!$E$2:$E$2000,'Mutasi stok'!$B$2:$B$2000,"Masuk",'Mutasi stok'!$C$2:$C$2000,"Bahan",'Mutasi stok'!$D$2:$D$2000,$A10) -> 10 | F10: =SUMIFS('Mutasi stok'!$E$2:$E$2000,'Mutasi stok'!$B$2:$B$2000,"Koreksi",'Mutasi stok'!$C$2:$C$2000,"Bahan",'Mutasi stok'!$D$2:$D$2000,$A10) -> 0 | G10: =IF(C10="Per pesanan",D10*SUMPRODUCT(Pesanan!$W$2:$W$1000),IF(C10="Per kit",D10*SUMPRODUCT(Pesanan!$W$2:$W$1000*(Pesanan!$AE$2:$AE$1000=1)),IF(C10="Per LED",D10*SUMPRODUCT(Pesanan!$W$2:$W$1000*(Pesanan!$AF$2:$AF$1000=1)),0))) -> 2 | H10: =SUMIFS('Mutasi stok'!$E$2:$E$2000,'Mutasi stok'!$B$2:$B$2000,"Pakai",'Mutasi stok'!$C$2:$C$2000,"Bahan",'Mutasi stok'!$D$2:$D$2000,$A10) -> 0 | I10: =E10+F10-G10-H10 -> 8 | J10: 5 | K10: =IF(I10<J10,"PESAN","OK") -> OK | L10: Hanya dipakai bila kode TIDAK berakhiran -TK | M10: =IF(O10=0,"",INDEX('Mutasi stok'!$G$2:$G$2000,O10)/INDEX('Mutasi stok'!$E$2:$E$2000,O10)) -> 35000 | N10: =IF(K10="PESAN",COUNTIF($K$5:K10,"PESAN"),"") | O10: =SUMPRODUCT(MAX(('Mutasi stok'!$D$2:$D$2000=$A10)*('Mutasi stok'!$B$2:$B$2000="Masuk")*('Mutasi stok'!$G$2:$G$2000>0)*(ROW('Mutasi stok'!$D$2:$D$2000)-1))) -> 11
A11: Bohlam LED 5 W | B11: pcs | C11: Per LED | D11: 1 | E11: =SUMIFS('Mutasi stok'!$E$2:$E$2000,'Mutasi stok'!$B$2:$B$2000,"Masuk",'Mutasi stok'!$C$2:$C$2000,"Bahan",'Mutasi stok'!$D$2:$D$2000,$A11) -> 10 | F11: =SUMIFS('Mutasi stok'!$E$2:$E$2000,'Mutasi stok'!$B$2:$B$2000,"Koreksi",'Mutasi stok'!$C$2:$C$2000,"Bahan",'Mutasi stok'!$D$2:$D$2000,$A11) -> 0 | G11: =IF(C11="Per pesanan",D11*SUMPRODUCT(Pesanan!$W$2:$W$1000),IF(C11="Per kit",D11*SUMPRODUCT(Pesanan!$W$2:$W$1000*(Pesanan!$AE$2:$AE$1000=1)),IF(C11="Per LED",D11*SUMPRODUCT(Pesanan!$W$2:$W$1000*(Pesanan!$AF$2:$AF$1000=1)),0))) -> 1 | H11: =SUMIFS('Mutasi stok'!$E$2:$E$2000,'Mutasi stok'!$B$2:$B$2000,"Pakai",'Mutasi stok'!$C$2:$C$2000,"Bahan",'Mutasi stok'!$D$2:$D$2000,$A11) -> 0 | I11: =E11+F11-G11-H11 -> 9 | J11: 5 | K11: =IF(I11<J11,"PESAN","OK") -> OK | L11: Hanya dipakai bila kode berakhiran -LED | M11: =IF(O11=0,"",INDEX('Mutasi stok'!$G$2:$G$2000,O11)/INDEX('Mutasi stok'!$E$2:$E$2000,O11)) -> 15000 | N11: =IF(K11="PESAN",COUNTIF($K$5:K11,"PESAN"),"") | O11: =SUMPRODUCT(MAX(('Mutasi stok'!$D$2:$D$2000=$A11)*('Mutasi stok'!$B$2:$B$2000="Masuk")*('Mutasi stok'!$G$2:$G$2000>0)*(ROW('Mutasi stok'!$D$2:$D$2000)-1))) -> 12
A12: Pemberat alas | B12: pcs | C12: Per pesanan | D12: 1 | E12: =SUMIFS('Mutasi stok'!$E$2:$E$2000,'Mutasi stok'!$B$2:$B$2000,"Masuk",'Mutasi stok'!$C$2:$C$2000,"Bahan",'Mutasi stok'!$D$2:$D$2000,$A12) -> 20 | F12: =SUMIFS('Mutasi stok'!$E$2:$E$2000,'Mutasi stok'!$B$2:$B$2000,"Koreksi",'Mutasi stok'!$C$2:$C$2000,"Bahan",'Mutasi stok'!$D$2:$D$2000,$A12) -> 0 | G12: =IF(C12="Per pesanan",D12*SUMPRODUCT(Pesanan!$W$2:$W$1000),IF(C12="Per kit",D12*SUMPRODUCT(Pesanan!$W$2:$W$1000*(Pesanan!$AE$2:$AE$1000=1)),IF(C12="Per LED",D12*SUMPRODUCT(Pesanan!$W$2:$W$1000*(Pesanan!$AF$2:$AF$1000=1)),0))) -> 2 | H12: =SUMIFS('Mutasi stok'!$E$2:$E$2000,'Mutasi stok'!$B$2:$B$2000,"Pakai",'Mutasi stok'!$C$2:$C$2000,"Bahan",'Mutasi stok'!$D$2:$D$2000,$A12) -> 0 | I12: =E12+F12-G12-H12 -> 18 | J12: 10 | K12: =IF(I12<J12,"PESAN","OK") -> OK | L12: Isi pemberat alas (baut/semen/besi), ganti sesuai yang dipakai | M12: =IF(O12=0,"",INDEX('Mutasi stok'!$G$2:$G$2000,O12)/INDEX('Mutasi stok'!$E$2:$E$2000,O12)) -> 5000 | N12: =IF(K12="PESAN",COUNTIF($K$5:K12,"PESAN"),"") | O12: =SUMPRODUCT(MAX(('Mutasi stok'!$D$2:$D$2000=$A12)*('Mutasi stok'!$B$2:$B$2000="Masuk")*('Mutasi stok'!$G$2:$G$2000>0)*(ROW('Mutasi stok'!$D$2:$D$2000)-1))) -> 16
